Workbook
Name ASM_LTM_EBITDA: Assumptions!$C$5
Name ASM_ENTRY_MULT: Assumptions!$C$6
Name ASM_ENTRY_EV: Assumptions!$C$7
Name ASM_TRANS_FEES: Assumptions!$C$8
Name ASM_FIN_FEES: Assumptions!$C$9
Name ASM_MGMT_ROLLOVER: Assumptions!$C$10
Name ASM_TLB_AMT: Assumptions!$D$15
Name ASM_TLB_RATE: Assumptions!$E$15
Name ASM_TLB_CAMRT: Assumptions!$F$15
Name ASM_SSN_AMT: Assumptions!$D$16
Name ASM_SSN_RATE: Assumptions!$E$16
Name ASM_MEZ_AMT: Assumptions!$D$17
Name ASM_MEZ_RATE: Assumptions!$E$17
Name ASM_MEZ_PIK: Assumptions!$G$17
Name ASM_TOT_DEBT: Assumptions!$D$19
Name ASM_EQUITY: Assumptions!$D$20
Name ASM_REV_LTM: Assumptions!$C$27
Name ASM_EBITDA_LTM: Assumptions!$C$28
Name ASM_DA_LTM: Assumptions!$C$30
Name ASM_EBIT_LTM: Assumptions!$C$31
Name ASM_CAPEX_LTM: Assumptions!$C$33
Name ASM_NWC_LTM: Assumptions!$C$34
Name ASM_EXIT_YEAR: Assumptions!$C$50
Name ASM_EXIT_MULT: Assumptions!$C$51
Name ASM_EXIT_FEE: Assumptions!$C$52
Name ASM_REV_Y1: Assumptions!$D$27
Name ASM_REV_Y2: Assumptions!$E$27
Name ASM_REV_Y3: Assumptions!$F$27
Name ASM_REV_Y4: Assumptions!$G$27
Name ASM_REV_Y5: Assumptions!$H$27
Name ASM_EBITDA_Y1: Assumptions!$D$28
Name ASM_EBITDA_Y2: Assumptions!$E$28
Name ASM_EBITDA_Y3: Assumptions!$F$28
Name ASM_EBITDA_Y4: Assumptions!$G$28
Name ASM_EBITDA_Y5: Assumptions!$H$28
Name ASM_DA_Y1: Assumptions!$D$30
Name ASM_DA_Y2: Assumptions!$E$30
Name ASM_DA_Y3: Assumptions!$F$30
Name ASM_DA_Y4: Assumptions!$G$30
Name ASM_DA_Y5: Assumptions!$H$30
Name ASM_EBIT_Y1: Assumptions!$D$31
Name ASM_EBIT_Y2: Assumptions!$E$31
Name ASM_EBIT_Y3: Assumptions!$F$31
Name ASM_EBIT_Y4: Assumptions!$G$31
Name ASM_EBIT_Y5: Assumptions!$H$31
Name ASM_CAPEX_Y1: Assumptions!$D$33
Name ASM_CAPEX_Y2: Assumptions!$E$33
Name ASM_CAPEX_Y3: Assumptions!$F$33
Name ASM_CAPEX_Y4: Assumptions!$G$33
Name ASM_CAPEX_Y5: Assumptions!$H$33
Name ASM_NWC_Y1: Assumptions!$D$34
Name ASM_NWC_Y2: Assumptions!$E$34
Name ASM_NWC_Y3: Assumptions!$F$34
Name ASM_NWC_Y4: Assumptions!$G$34
Name ASM_NWC_Y5: Assumptions!$H$34
Name ASM_TAX_Y1: Assumptions!$D$35
Name ASM_TAX_Y2: Assumptions!$E$35
Name ASM_TAX_Y3: Assumptions!$F$35
Name ASM_TAX_Y4: Assumptions!$G$35
Name ASM_TAX_Y5: Assumptions!$H$35

Sheet Assumptions
B1: LBO MODEL — ASSUMPTIONS
B2: Yellow + Blue font = hard-coded input (you must fill these) Black = same-sheet formula Green = linked from another sheet Purple = external file link
B5: LTM EBITDA ($M) [links to Block 3 — enter value there] | C5: =$C$28
B6: Entry EV / EBITDA Multiple (x) | C6: 10
B7: Entry Enterprise Value ($M) [= LTM EBITDA × Multiple] | C7: =$C$5*$C$6
B8: Transaction Fees (% of EV) | C8: 0.02
B9: Financing Fees (% of Total Debt) | C9: 0.015
B10: Management Rollover (% of Equity) | C10: 0.1
B12: 2. DEBT STRUCTURE
B13: Tranche | C13: % of EV | D13: $ Amount ($M) | E13: Interest Rate | F13: Cash Amort %/yr | G13: PIK Rate
B14: Revolving Credit (capacity, undrawn) | C14: 0.1 | D14: =$C$14*$C$7 | E14: 0.045 | F14: 0 | G14: 0
B15: Term Loan B | C15: 0.35 | D15: =$C$15*$C$7 | E15: 0.055 | F15: 0.01 | G15: 0
B16: Senior Secured Notes | C16: 0.2 | D16: =$C$16*$C$7 | E16: 0.065 | F16: 0 | G16: 0
B17: Mezzanine | C17: 0.1 | D17: =$C$17*$C$7 | E17: 0.09 | F17: 0 | G17: 0.02
B19: Total Drawn Debt | D19: =SUM($D$15:$D$17)
B20: Sponsor Equity (plug) | D20: =$C$7*(1+$C$8)-$D$19
B23: 3. OPERATING ASSUMPTIONS
B24: SECTION A — LTM actuals in $M (yellow = enter here) + Year 1-5 auto-projected
C26: LTM | D26: Year 1 | E26: Year 2 | F26: Year 3 | G26: Year 4 | H26: Year 5
B27: Revenue ($M) | C27: 400 | D27: =$C$27*(1+$D$45) | E27: =$D$27*(1+$E$45) | F27: =$E$27*(1+$F$45) | G27: =$F$27*(1+$G$45) | H27: =$G$27*(1+$H$45)
B28: EBITDA ($M) | C28: 100 | D28: =$D$27*$D$38 | E28: =$E$27*$E$38 | F28: =$F$27*$F$38 | G28: =$G$27*$G$38 | H28: =$H$27*$H$38
B30: D&A ($M) | C30: 20 | D30: =$D$27*$C$39 | E30: =$E$27*$C$39 | F30: =$F$27*$C$39 | G30: =$G$27*$C$39 | H30: =$H$27*$C$39
B31: EBIT ($M) [= EBITDA − D&A] | C31: =$C$28-$C$30 | D31: =$D$28-$D$30 | E31: =$E$28-$E$30 | F31: =$F$28-$F$30 | G31: =$G$28-$G$30 | H31: =$H$28-$H$30
B33: CapEx ($M) | C33: 16 | D33: =$D$27*$C$41 | E33: =$E$27*$C$41 | F33: =$F$27*$C$41 | G33: =$G$27*$C$41 | H33: =$H$27*$C$41
B34: Change in NWC ($M) | C34: 8 | D34: =$D$27*$C$42 | E34: =$E$27*$C$42 | F34: =$F$27*$C$42 | G34: =$G$27*$C$42 | H34: =$H$27*$C$42
B35: Tax Rate (%) [external: set by legislation — must be input] | C35: 0.25 | D35: 0.25 | E35: 0.25 | F35: 0.25 | G35: 0.25 | H35: 0.25
B37: SECTION B — Derived % ratios (black = same-sheet formula) | C37: LTM | D37: Year 1 | E37: Year 2 | F37: Year 3 | G37: Year 4 | H37: Year 5
B38: EBITDA Margin (%) [LTM = actual; Y1-5 = LTM + cumulative expansion] | C38: =IFERROR($C$28/$C$27,0) | D38: =$C$38+$C$46 | E38: =$D$38+$C$46 | F38: =$E$38+$C$46 | G38: =$F$38+$C$46 | H38: =$G$38+$C$46
B39: D&A (% of Revenue) [constant = LTM ratio applied to all years] | C39: =IFERROR($C$30/$C$27,0) | D39: =IFERROR($D$30/$D$27,0) | E39: =IFERROR($E$30/$E$27,0) | F39: =IFERROR($F$30/$F$27,0) | G39: =IFERROR($G$30/$G$27,0) | H39: =IFERROR($H$30/$H$27,0)
B40: EBIT Margin (%) | C40: =IFERROR($C$31/$C$27,0) | D40: =IFERROR($D$31/$D$27,0) | E40: =IFERROR($E$31/$E$27,0) | F40: =IFERROR($F$31/$F$27,0) | G40: =IFERROR($G$31/$G$27,0) | H40: =IFERROR($H$31/$H$27,0)
B41: CapEx (% of Revenue) [constant = LTM ratio] | C41: =IFERROR($C$33/$C$27,0) | D41: =IFERROR($D$33/$D$27,0) | E41: =IFERROR($E$33/$E$27,0) | F41: =IFERROR($F$33/$F$27,0) | G41: =IFERROR($G$33/$G$27,0) | H41: =IFERROR($H$33/$H$27,0)
B42: NWC Change (% of Revenue) [constant = LTM ratio] | C42: =IFERROR($C$34/$C$27,0) | D42: =IFERROR($D$34/$D$27,0) | E42: =IFERROR($E$34/$E$27,0) | F42: =IFERROR($F$34/$F$27,0) | G42: =IFERROR($G$34/$G$27,0) | H42: =IFERROR($H$34/$H$27,0)
B44: SECTION C — Forward growth drivers (yellow cells drive all of Section A Years 1-5) | C44: LTM | D44: Year 1 | E44: Year 2 | F44: Year 3 | G44: Year 4 | H44: Year 5
B45: Revenue Growth Rate (%/year) | C45: n/a | D45: 0.05 | E45: 0.05 | F45: 0.05 | G45: 0.05 | H45: 0.05
B46: Annual EBITDA Margin Improvement (%/yr) [0 = flat | 0.005 = +50bps/yr | drives row 38] | C46: 0.005
B48: 4. EXIT ASSUMPTIONS
B50: Exit Year (1-5) | C50: 5
B51: Exit EV / EBITDA Multiple (x) | C51: 11
B52: Exit Fee (% of Exit EV) | C52: 0.015
B56: 5. BALANCE SHEET OPENING BALANCES AT CLOSE
...

Sheet Sources_Uses
B1: SOURCES & USES
B2: Transaction financing at close | Sources must equal Uses |
C3: Amount ($M) | D3: % of Total | E3: % of EV
B4: SOURCES — Where the money comes from
B5: Debt
B6: Term Loan B (senior, floating rate, ~1% annual amortisation) | C6: =Assumptions!$D$15 | D6: =$C$6/$C$14 | E6: =$C$6/Assumptions!$C$7
B7: Senior Secured Notes (fixed rate, bullet maturity) | C7: =Assumptions!$D$16 | D7: =$C$7/$C$14 | E7: =$C$7/Assumptions!$C$7
B8: Mezzanine (junior debt, highest rate, partial PIK) | C8: =Assumptions!$D$17 | D8: =$C$8/$C$14 | E8: =$C$8/Assumptions!$C$7
B9: Total Debt | C9: =SUM($C$6:$C$8) | D9: =$C$9/$C$14 | E9: =$C$9/Assumptions!$C$7
B10: Equity
B11: Sponsor Equity (PE fund cash contribution) | C11: =(Assumptions!$C$7*(1+Assumptions!$C$8)+$C$9*Assumptions!$C$9-$C$9)*(1-Assumptions!$C$10) | D11: =$C$11/$C$14 | E11: =$C$11/Assumptions!$C$7
B12: Management Rollover (non-cash — existing equity retained by mgmt) | C12: =(Assumptions!$C$7*(1+Assumptions!$C$8)+$C$9*Assumptions!$C$9-$C$9)*Assumptions!$C$10 | D12: =$C$12/$C$14 | E12: =$C$12/Assumptions!$C$7
B13: Total Equity | C13: =$C$11+$C$12 | D13: =$C$13/$C$14 | E13: =$C$13/Assumptions!$C$7
B14: TOTAL SOURCES | C14: =$C$9+$C$13 | D14: =$C$14/$C$14 | E14: =$C$14/Assumptions!$C$7
B16: USES — Where the money goes
B17: Transaction Costs
B18: Purchase Price (= Entry Enterprise Value) | C18: =Assumptions!$C$7 | D18: =$C$18/$C$21 | E18: =$C$18/Assumptions!$C$7
B19: Transaction Fees (advisory, legal, accounting) | C19: =Assumptions!$C$7*Assumptions!$C$8 | D19: =$C$19/$C$21 | E19: =$C$19/Assumptions!$C$7
B20: Financing Fees (debt arrangement, OID, syndication) | C20: =$C$9*Assumptions!$C$9 | D20: =$C$20/$C$21 | E20: =$C$20/Assumptions!$C$7
B21: TOTAL USES | C21: =SUM($C$18:$C$20) | D21: =$C$21/$C$21 | E21: =$C$21/Assumptions!$C$7
B23: CHECK: Sources − Uses (must = $0.0) | C23: =$C$14-$C$21
B25: KEY LEVERAGE METRICS AT CLOSE
B26: Total Debt / LTM EBITDA (Leverage Ratio) | C26: =$C$9/Assumptions!$C$5 | D26: Typical range: 4.5x – 6.5x
B27: Total Equity / Entry EV (Equity Contribution) | C27: =$C$13/Assumptions!$C$7 | D27: Typical range: 30% – 45%
B28: EBITDA / Interest (Coverage Ratio, Year 1 approx.) | C28: =(Assumptions!$C$28)/(Assumptions!$D$15*Assumptions!$E$15+Assumptions!$D$16*Assumptions!$E$16+Assumptions!$D$17*(Assumptions!$E$17-Assumptions!$G$17)) | D28: Must be > 2.0x

Sheet Income_Stmt
B1: INCOME STATEMENT
B2: All figures $M | Interest from Debt Schedule (Year 1-5) |
B3: PROJECTED INCOME STATEMENT ($M)
C4: LTM | D4: Year 1 | E4: Year 2 | F4: Year 3 | G4: Year 4 | H4: Year 5
B6: Revenue | C6: =Assumptions!$C$27 | D6: =Assumptions!$D$27 | E6: =Assumptions!$E$27 | F6: =Assumptions!$F$27 | G6: =Assumptions!$G$27 | H6: =Assumptions!$H$27
B7: YoY Growth | C7: — | D7: =$D$6/$C$6-1 | E7: =$E$6/$D$6-1 | F7: =$F$6/$E$6-1 | G7: =$G$6/$F$6-1 | H7: =$H$6/$G$6-1
B9: EBITDA | C9: =Assumptions!$C$28 | D9: =Assumptions!$D$28 | E9: =Assumptions!$E$28 | F9: =Assumptions!$F$28 | G9: =Assumptions!$G$28 | H9: =Assumptions!$H$28
B10: EBITDA Margin | C10: =$C$9/$C$6 | D10: =$D$9/$D$6 | E10: =$E$9/$E$6 | F10: =$F$9/$F$6 | G10: =$G$9/$G$6 | H10: =$H$9/$H$6
B11: Depreciation & Amortisation (D&A) | C11: =Assumptions!$C$30 | D11: =Assumptions!$D$30 | E11: =Assumptions!$E$30 | F11: =Assumptions!$F$30 | G11: =Assumptions!$G$30 | H11: =Assumptions!$H$30
B12: EBIT (Operating Profit) | C12: =$C$9-$C$11 | D12: =$D$9-$D$11 | E12: =$E$9-$E$11 | F12: =$F$9-$F$11 | G12: =$G$9-$G$11 | H12: =$H$9-$H$11
B13: EBIT Margin | C13: =$C$12/$C$6 | D13: =$D$12/$D$6 | E13: =$E$12/$E$6 | F13: =$F$12/$F$6 | G13: =$G$12/$G$6 | H13: =$H$12/$H$6
B14: Interest Expense (LTM = simplified | Year 1-5 = from Debt Schedule)
B15: Interest — Term Loan B | C15: =Assumptions!$D$15*Assumptions!$E$15 | D15: =Debt_Schedule!$D$12 | E15: =Debt_Schedule!$E$12 | F15: =Debt_Schedule!$F$12 | G15: =Debt_Schedule!$G$12 | H15: =Debt_Schedule!$H$12
B16: Interest — Senior Secured Notes | C16: =Assumptions!$D$16*Assumptions!$E$16 | D16: =Debt_Schedule!$D$20 | E16: =Debt_Schedule!$E$20 | F16: =Debt_Schedule!$F$20 | G16: =Debt_Schedule!$G$20 | H16: =Debt_Schedule!$H$20
B17: Interest — Mezzanine (cash + PIK = full P&L charge) | C17: =Assumptions!$D$17*Assumptions!$E$17 | D17: =Debt_Schedule!$D$28+Debt_Schedule!$D$29 | E17: =Debt_Schedule!$E$28+Debt_Schedule!$E$29 | F17: =Debt_Schedule!$F$28+Debt_Schedule!$F$29 | G17: =Debt_Schedule!$G$28+Debt_Schedule!$G$29 | H17: =Debt_Schedule!$H$28+Debt_Schedule!$H$29
B18: Total Interest Expense | C18: =SUM($C$15:$C$17) | D18: =SUM($D$15:$D$17) | E18: =SUM($E$15:$E$17) | F18: =SUM($F$15:$F$17) | G18: =SUM($G$15:$G$17) | H18: =SUM($H$15:$H$17)
B20: EBT (Earnings Before Tax) | C20: =$C$12-$C$18 | D20: =$D$12-$D$18 | E20: =$E$12-$E$18 | F20: =$F$12-$F$18 | G20: =$G$12-$G$18 | H20: =$H$12-$H$18
B21: Tax Expense | C21: =MAX($C$20*Assumptions!$C$35,0) | D21: =MAX($D$20*Assumptions!$D$35,0) | E21: =MAX($E$20*Assumptions!$E$35,0) | F21: =MAX($F$20*Assumptions!$F$35,0) | G21: =MAX($G$20*Assumptions!$G$35,0) | H21: =MAX($H$20*Assumptions!$H$35,0)
B22: NET INCOME | C22: =$C$20-$C$21 | D22: =$D$20-$D$21 | E22: =$E$20-$E$21 | F22: =$F$20-$F$21 | G22: =$G$20-$G$21 | H22: =$H$20-$H$21
B23: Net Income Margin | C23: =IFERROR($C$22/$C$6,0) | D23: =IFERROR($D$22/$D$6,0) | E23: =IFERROR($E$22/$E$6,0) | F23: =IFERROR($F$22/$F$6,0) | G23: =IFERROR($G$22/$G$6,0) | H23: =IFERROR($H$22/$H$6,0)

Sheet Debt_Schedule
B1: DEBT SCHEDULE
B2: Tracks balance, amortisation, cash sweep and interest for all tranches |
B3: DEBT SCHEDULE ($M)
C4: Year 0 (close) | D4: Year 1 | E4: Year 2 | F4: Year 3 | G4: Year 4 | H4: Year 5
B6: TERM LOAN B
B7: Beginning Balance | C7: =Assumptions!$D$15 | D7: =$C$10 | E7: =$D$10 | F7: =$E$10 | G7: =$F$10 | H7: =$G$10
B8: (-) Mandatory Amortisation | C8: =0 | D8: =MIN(Assumptions!$D$15*Assumptions!$F$15,$D$7) | E8: =MIN(Assumptions!$D$15*Assumptions!$F$15,$E$7) | F8: =MIN(Assumptions!$D$15*Assumptions!$F$15,$F$7) | G8: =MIN(Assumptions!$D$15*Assumptions!$F$15,$G$7) | H8: =MIN(Assumptions!$D$15*Assumptions!$F$15,$H$7)
B9: (-) Optional Paydown (cash sweep — FIRST priority in waterfall) | C9: =0 | D9: =MIN(MAX(Cash_Flow!$D$13,0),MAX($D$7-$D$8,0)) | E9: =MIN(MAX(Cash_Flow!$E$13,0),MAX($E$7-$E$8,0)) | F9: =MIN(MAX(Cash_Flow!$F$13,0),MAX($F$7-$F$8,0)) | G9: =MIN(MAX(Cash_Flow!$G$13,0),MAX($G$7-$G$8,0)) | H9: =MIN(MAX(Cash_Flow!$H$13,0),MAX($H$7-$H$8,0))
B10: Ending Balance | C10: =$C$7 | D10: =MAX($D$7-$D$8-$D$9,0) | E10: =MAX($E$7-$E$8-$E$9,0) | F10: =MAX($F$7-$F$8-$F$9,0) | G10: =MAX($G$7-$G$8-$G$9,0) | H10: =MAX($H$7-$H$8-$H$9,0)
B12: Cash Interest (= Beginning Balance × Rate) | C12: =0 | D12: =$D$7*Assumptions!$E$15 | E12: =$E$7*Assumptions!$E$15 | F12: =$F$7*Assumptions!$E$15 | G12: =$G$7*Assumptions!$E$15 | H12: =$H$7*Assumptions!$E$15
B14: SENIOR SECURED NOTES
B15: Beginning Balance | C15: =Assumptions!$D$16 | D15: =$C$18 | E15: =$D$18 | F15: =$E$18 | G15: =$F$18 | H15: =$G$18
B16: (-) Mandatory Amortisation (none — bullet bond, repaid at maturity) | C16: =0 | D16: =0 | E16: =0 | F16: =0 | G16: =0 | H16: =0
B17: (-) Optional Paydown (SECOND priority — remainder after TLB) | C17: =0 | D17: =MIN(MAX(Cash_Flow!$D$13-$D$9,0),MAX($D$15,0)) | E17: =MIN(MAX(Cash_Flow!$E$13-$E$9,0),MAX($E$15,0)) | F17: =MIN(MAX(Cash_Flow!$F$13-$F$9,0),MAX($F$15,0)) | G17: =MIN(MAX(Cash_Flow!$G$13-$G$9,0),MAX($G$15,0)) | H17: =MIN(MAX(Cash_Flow!$H$13-$H$9,0),MAX($H$15,0))
B18: Ending Balance | C18: =$C$15 | D18: =MAX($D$15-$D$17,0) | E18: =MAX($E$15-$E$17,0) | F18: =MAX($F$15-$F$17,0) | G18: =MAX($G$15-$G$17,0) | H18: =MAX($H$15-$H$17,0)
B20: Cash Interest (= Beginning Balance × Rate) | C20: =0 | D20: =$D$15*Assumptions!$E$16 | E20: =$E$15*Assumptions!$E$16 | F20: =$F$15*Assumptions!$E$16 | G20: =$G$15*Assumptions!$E$16 | H20: =$H$15*Assumptions!$E$16
B22: MEZZANINE
B23: Beginning Balance | C23: =Assumptions!$D$17 | D23: =$C$26 | E23: =$D$26 | F23: =$E$26 | G23: =$F$26 | H23: =$G$26
B24: (+) PIK Accrual (non-cash — accretes to principal balance) | C24: =0 | D24: =$D$23*Assumptions!$G$17 | E24: =$E$23*Assumptions!$G$17 | F24: =$F$23*Assumptions!$G$17 | G24: =$G$23*Assumptions!$G$17 | H24: =$H$23*Assumptions!$G$17
B25: (-) Optional Paydown (THIRD priority — remainder after TLB and SSN) | C25: =0 | D25: =MIN(MAX(Cash_Flow!$D$13-$D$9-$D$17,0),MAX($D$23+$D$24,0)) | E25: =MIN(MAX(Cash_Flow!$E$13-$E$9-$E$17,0),MAX($E$23+$E$24,0)) | F25: =MIN(MAX(Cash_Flow!$F$13-$F$9-$F$17,0),MAX($F$23+$F$24,0)) | G25: =MIN(MAX(Cash_Flow!$G$13-$G$9-$G$17,0),MAX($G$23+$G$24,0)) | H25: =MIN(MAX(Cash_Flow!$H$13-$H$9-$H$17,0),MAX($H$23+$H$24,0))
B26: Ending Balance | C26: =$C$23 | D26: =MAX($D$23+$D$24-$D$25,0) | E26: =MAX($E$23+$E$24-$E$25,0) | F26: =MAX($F$23+$F$24-$F$25,0) | G26: =MAX($G$23+$G$24-$G$25,0) | H26: =MAX($H$23+$H$24-$H$25,0)
B28: Cash Interest (= Beginning × (Total Rate − PIK Rate)) | C28: =0 | D28: =$D$23*(Assumptions!$E$17-Assumptions!$G$17) | E28: =$E$23*(Assumptions!$E$17-Assumptions!$G$17) | F28: =$F$23*(Assumptions!$E$17-Assumptions!$G$17) | G28: =$G$23*(Assumptions!$E$17-Assumptions!$G$17) | H28: =$H$23*(Assumptions!$E$17-Assumptions!$G$17)
B29: PIK Interest (non-cash — same as PIK accrual above) | C29: =0 | D29: =$D$24 | E29: =$E$24 | F29: =$F$24 | G29: =$G$24 | H29: =$H$24
B31: SUMMARY
C32: Year 0 (close) | D32: Year 1 | E32: Year 2 | F32: Year 3 | G32: Year 4 | H32: Year 5
B33: Total Debt (ending balance) | C33: =$C$10+$C$18+$C$26 | D33: =$D$10+$D$18+$D$26 | E33: =$E$10+$E$18+$E$26 | F33: =$F$10+$F$18+$F$26 | G33: =$G$10+$G$18+$G$26 | H33: =$H$10+$H$18+$H$26
B34: Total Cash Interest [→ used by Cash Flow and IS] | C34: =$C$12+$C$20+$C$28 | D34: =$D$12+$D$20+$D$28 | E34: =$E$12+$E$20+$E$28 | F34: =$F$12+$F$20+$F$28 | G34: =$G$12+$G$20+$G$28 | H34: =$H$12+$H$20+$H$28
B35: Total PIK Interest (non-cash) | C35: =$C$29 | D35: =$D$29 | E35: =$E$29 | F35: =$F$29 | G35: =$G$29 | H35: =$H$29
B36: Total Interest (cash + PIK) | C36: =$C$34+$C$35 | D36: =$D$34+$D$35 | E36: =$E$34+$E$35 | F36: =$F$34+$F$35 | G36: =$G$34+$G$35 | H36: =$H$34+$H$35
B37: Total Mandatory Amortisation [→ used by Cash Flow] | C37: =$C$8+$C$16 | D37: =$D$8+$D$16 | E37: =$E$8+$E$16 | F37: =$F$8+$F$16 | G37: =$G$8+$G$16 | H37: =$H$8+$H$16

Sheet Cash_Flow
B1: CASH FLOW STATEMENT
B2: EBITDA → Operating FCF → debt service → ending cash balance |
B3: FREE CASH FLOW ($M)
C4: Year 0 | D4: Year 1 | E4: Year 2 | F4: Year 3 | G4: Year 4 | H4: Year 5
C5: ← deal close
B6: EBITDA | C6: — | D6: =Assumptions!$D$28 | E6: =Assumptions!$E$28 | F6: =Assumptions!$F$28 | G6: =Assumptions!$G$28 | H6: =Assumptions!$H$28
B7: (-) Cash Interest Expense [from Debt Schedule — actual declining balances] | C7: — | D7: =Debt_Schedule!$D$34 | E7: =Debt_Schedule!$E$34 | F7: =Debt_Schedule!$F$34 | G7: =Debt_Schedule!$G$34 | H7: =Debt_Schedule!$H$34
B8: (-) Cash Taxes [= MAX((EBITDA − D&A − Total Interest incl. PIK) × Rate, 0)] | C8: — | D8: =MAX((Assumptions!$D$28-Assumptions!$D$30-Debt_Schedule!$D$36)*Assumptions!$D$35,0) | E8: =MAX((Assumptions!$E$28-Assumptions!$E$30-Debt_Schedule!$E$36)*Assumptions!$E$35,0) | F8: =MAX((Assumptions!$F$28-Assumptions!$F$30-Debt_Schedule!$F$36)*Assumptions!$F$35,0) | G8: =MAX((Assumptions!$G$28-Assumptions!$G$30-Debt_Schedule!$G$36)*Assumptions!$G$35,0) | H8: =MAX((Assumptions!$H$28-Assumptions!$H$30-Debt_Schedule!$H$36)*Assumptions!$H$35,0)
B9: (-) Capital Expenditure (CapEx) | C9: — | D9: =Assumptions!$D$33 | E9: =Assumptions!$E$33 | F9: =Assumptions!$F$33 | G9: =Assumptions!$G$33 | H9: =Assumptions!$H$33
B10: (-) Increase in Net Working Capital (NWC) | C10: — | D10: =Assumptions!$D$34 | E10: =Assumptions!$E$34 | F10: =Assumptions!$F$34 | G10: =Assumptions!$G$34 | H10: =Assumptions!$H$34
B11: Operating Free Cash Flow | C11: — | D11: =$D$6-$D$7-$D$8-$D$9-$D$10 | E11: =$E$6-$E$7-$E$8-$E$9-$E$10 | F11: =$F$6-$F$7-$F$8-$F$9-$F$10 | G11: =$G$6-$G$7-$G$8-$G$9-$G$10 | H11: =$H$6-$H$7-$H$8-$H$9-$H$10
B12: (-) Mandatory Debt Amortisation [from Debt Schedule] | C12: — | D12: =Debt_Schedule!$D$37 | E12: =Debt_Schedule!$E$37 | F12: =Debt_Schedule!$F$37 | G12: =Debt_Schedule!$G$37 | H12: =Debt_Schedule!$H$37
B13: Cash Available for Optional Debt Sweep [⬅ Debt Schedule reads this row] | C13: — | D13: =MAX($D$11-$D$12,0) | E13: =MAX($E$11-$E$12,0) | F13: =MAX($F$11-$F$12,0) | G13: =MAX($G$11-$G$12,0) | H13: =MAX($H$11-$H$12,0)
B14: (-) Optional Cash Sweep [sum from Debt Schedule: TLB + SSN + MEZ] | C14: — | D14: =Debt_Schedule!$D$9+Debt_Schedule!$D$17+Debt_Schedule!$D$25 | E14: =Debt_Schedule!$E$9+Debt_Schedule!$E$17+Debt_Schedule!$E$25 | F14: =Debt_Schedule!$F$9+Debt_Schedule!$F$17+Debt_Schedule!$F$25 | G14: =Debt_Schedule!$G$9+Debt_Schedule!$G$17+Debt_Schedule!$G$25 | H14: =Debt_Schedule!$H$9+Debt_Schedule!$H$17+Debt_Schedule!$H$25
B15: Net Cash Retained on Balance Sheet | C15: — | D15: =$D$13-$D$14 | E15: =$E$13-$E$14 | F15: =$F$13-$F$14 | G15: =$G$13-$G$14 | H15: =$H$13-$H$14
B16: Beginning Cash Balance | C16: =0 | D16: =$C$17 | E16: =$D$17 | F16: =$E$17 | G16: =$F$17 | H16: =$G$17
B17: Ending Cash Balance | C17: =0 | D17: =$D$16+$D$15 | E17: =$E$16+$E$15 | F17: =$F$16+$F$15 | G17: =$G$16+$G$15 | H17: =$H$16+$H$15

Sheet Balance_Sheet
B1: BALANCE SHEET
B2: Year 0 = deal close | CHECK row must show exactly 0.0 every year |
B3: BALANCE SHEET ($M)
C4: Year 0 (close) | D4: Year 1 | E4: Year 2 | F4: Year 3 | G4: Year 4 | H4: Year 5
B5: ASSETS
B6: Cash ($M) | C6: =0 | D6: =Cash_Flow!$D$17 | E6: =Cash_Flow!$E$17 | F6: =Cash_Flow!$F$17 | G6: =Cash_Flow!$G$17 | H6: =Cash_Flow!$H$17
B7: Net Working Capital ($M) | C7: =Assumptions!$C$59 | D7: =$C$7+Cash_Flow!$D$10 | E7: =$D$7+Cash_Flow!$E$10 | F7: =$E$7+Cash_Flow!$F$10 | G7: =$F$7+Cash_Flow!$G$10 | H7: =$G$7+Cash_Flow!$H$10
B8: PP&E (net book value, $M) | C8: =Assumptions!$C$58 | D8: =$C$8+Cash_Flow!$D$9-Assumptions!$D$30 | E8: =$D$8+Cash_Flow!$E$9-Assumptions!$E$30 | F8: =$E$8+Cash_Flow!$F$9-Assumptions!$F$30 | G8: =$F$8+Cash_Flow!$G$9-Assumptions!$G$30 | H8: =$G$8+Cash_Flow!$H$9-Assumptions!$H$30
B9: Goodwill ($M) [= EV×(1+fee%) − NWC − PP&E, constant] | C9: =Assumptions!$C$7*(1+Assumptions!$C$8)-Assumptions!$C$59-Assumptions!$C$58 | D9: =Assumptions!$C$7*(1+Assumptions!$C$8)-Assumptions!$C$59-Assumptions!$C$58 | E9: =Assumptions!$C$7*(1+Assumptions!$C$8)-Assumptions!$C$59-Assumptions!$C$58 | F9: =Assumptions!$C$7*(1+Assumptions!$C$8)-Assumptions!$C$59-Assumptions!$C$58 | G9: =Assumptions!$C$7*(1+Assumptions!$C$8)-Assumptions!$C$59-Assumptions!$C$58 | H9: =Assumptions!$C$7*(1+Assumptions!$C$8)-Assumptions!$C$59-Assumptions!$C$58
B10: Deferred Financing Costs ($M) [simplified: held constant] | C10: =Sources_Uses!$C$20 | D10: =Sources_Uses!$C$20 | E10: =Sources_Uses!$C$20 | F10: =Sources_Uses!$C$20 | G10: =Sources_Uses!$C$20 | H10: =Sources_Uses!$C$20
B11: TOTAL ASSETS | C11: =SUM($C$6:$C$10) | D11: =SUM($D$6:$D$10) | E11: =SUM($E$6:$E$10) | F11: =SUM($F$6:$F$10) | G11: =SUM($G$6:$G$10) | H11: =SUM($H$6:$H$10)
B13: LIABILITIES
B14: Term Loan B | C14: =Debt_Schedule!$C$10 | D14: =Debt_Schedule!$D$10 | E14: =Debt_Schedule!$E$10 | F14: =Debt_Schedule!$F$10 | G14: =Debt_Schedule!$G$10 | H14: =Debt_Schedule!$H$10
B15: Senior Secured Notes | C15: =Debt_Schedule!$C$18 | D15: =Debt_Schedule!$D$18 | E15: =Debt_Schedule!$E$18 | F15: =Debt_Schedule!$F$18 | G15: =Debt_Schedule!$G$18 | H15: =Debt_Schedule!$H$18
B16: Mezzanine (includes PIK accrual each year) | C16: =Debt_Schedule!$C$26 | D16: =Debt_Schedule!$D$26 | E16: =Debt_Schedule!$E$26 | F16: =Debt_Schedule!$F$26 | G16: =Debt_Schedule!$G$26 | H16: =Debt_Schedule!$H$26
B17: Total Debt | C17: =Debt_Schedule!$C$33 | D17: =Debt_Schedule!$D$33 | E17: =Debt_Schedule!$E$33 | F17: =Debt_Schedule!$F$33 | G17: =Debt_Schedule!$G$33 | H17: =Debt_Schedule!$H$33
B19: EQUITY
B20: Initial Equity Invested (constant) | C20: =Sources_Uses!$C$13 | D20: =Sources_Uses!$C$13 | E20: =Sources_Uses!$C$13 | F20: =Sources_Uses!$C$13 | G20: =Sources_Uses!$C$13 | H20: =Sources_Uses!$C$13
B21: Retained Earnings (cumulative Net Income from IS) | C21: =0 | D21: =$C$21+Income_Stmt!$D$22 | E21: =$D$21+Income_Stmt!$E$22 | F21: =$E$21+Income_Stmt!$F$22 | G21: =$F$21+Income_Stmt!$G$22 | H21: =$G$21+Income_Stmt!$H$22
B22: TOTAL EQUITY | C22: =$C$20+$C$21 | D22: =$D$20+$D$21 | E22: =$E$20+$E$21 | F22: =$F$20+$F$21 | G22: =$G$20+$G$21 | H22: =$H$20+$H$21
B24: Total Liabilities + Equity | C24: =$C$17+$C$22 | D24: =$D$17+$D$22 | E24: =$E$17+$E$22 | F24: =$F$17+$F$22 | G24: =$G$17+$G$22 | H24: =$H$17+$H$22
B25: CHECK Assets − (L + E) → must = 0.0 every year | C25: =$C$11-$C$24 | D25: =$D$11-$D$24 | E25: =$E$11-$E$24 | F25: =$F$11-$F$24 | G25: =$G$11-$G$24 | H25: =$H$11-$H$24

Sheet Returns
B1: RETURNS ANALYSIS
B2: Exit equity, MOIC, IRR | Sensitivity: entry multiple vs exit multiple |
B4: EXIT RETURNS SUMMARY
B5: Entry Equity Invested ($M) [from Sources & Uses] | C5: =Sources_Uses!$C$13
B6: Exit Year [from Assumptions] | C6: =Assumptions!$C$50
B7: Exit EBITDA ($M) [INDEX from Assumptions Y1-5] | C7: =INDEX('Assumptions'!$D$28:$H$28,Assumptions!$C$50)
B8: Exit EV / EBITDA Multiple (×) [from Assumptions] | C8: =Assumptions!$C$51
B9: Exit Enterprise Value ($M) [= Exit EBITDA × Exit Multiple] | C9: =$C$7*$C$8
B10: (-) Exit Total Debt ($M) [INDEX from Debt Schedule] | C10: =INDEX('Debt_Schedule'!$D$33:$H$33,Assumptions!$C$50)
B11: (+) Exit Cash Balance ($M) [INDEX from Cash Flow] | C11: =INDEX('Cash_Flow'!$D$17:$H$17,Assumptions!$C$50)
B12: (-) Exit Fee ($M) [= Exit EV × Exit Fee %] | C12: =$C$9*Assumptions!$C$52
B13: Exit Equity ($M) [= EV − Fee − Debt + Cash] | C13: =MAX($C$9-$C$12-$C$10+$C$11,0)
B14: MOIC (Multiple on Invested Capital) | C14: =IFERROR($C$13/$C$5,0)
B15: IRR (Internal Rate of Return) | C15: =IFERROR(IRR($C$18:$C$23,0.20),0)
B17: IRR HELPER CASH FLOWS (Year 0 = equity in; exit year = equity out)
B18: Year 0: −Entry Equity (fund invests) | C18: =-$C$5
B19: Year 1: + Exit Equity (only if exit year = 1) | C19: =IF(Assumptions!$C$50=1,$C$13,0)
B20: Year 2: + Exit Equity (only if exit year = 2) | C20: =IF(Assumptions!$C$50=2,$C$13,0)
B21: Year 3: + Exit Equity (only if exit year = 3) | C21: =IF(Assumptions!$C$50=3,$C$13,0)
B22: Year 4: + Exit Equity (only if exit year = 4) | C22: =IF(Assumptions!$C$50=4,$C$13,0)
B23: Year 5: + Exit Equity (only if exit year = 5) | C23: =IF(Assumptions!$C$50=5,$C$13,0)
B27: IRR SENSITIVITY (%) | Entry Multiple ↓ vs Exit Multiple →
B28: Debt held constant | Orange = base case | All else equal — only multiples vary
B29: Entry ↓ / Exit → | D29: 8 | E29: 9 | F29: 10 | G29: 11 | H29: 12 | I29: 13
C30: 8 | D30: =IFERROR((MAX(INDEX('Assumptions'!$D$28:$H$28,Assumptions!$C$50)*8*(1-Assumptions!$C$52)-INDEX('Debt_Schedule'!$D$33:$H$33,Assumptions!$C$50)+INDEX('Cash_Flow'!$D$17:$H$17,Assumptions!$C$50),0)/MAX(Assumptions!$C$28*8*(1+Assumptions!$C$8)-Sources_Uses!$C$9,1))^(1/MAX(Assumptions!$C$50,1))-1,"N/A") | E30: =IFERROR((MAX(INDEX('Assumptions'!$D$28:$H$28,Assumptions!$C$50)*9*(1-Assumptions!$C$52)-INDEX('Debt_Schedule'!$D$33:$H$33,Assumptions!$C$50)+INDEX('Cash_Flow'!$D$17:$H$17,Assumptions!$C$50),0)/MAX(Assumptions!$C$28*8*(1+Assumptions!$C$8)-Sources_Uses!$C$9,1))^(1/MAX(Assumptions!$C$50,1))-1,"N/A") | F30: =IFERROR((MAX(INDEX('Assumptions'!$D$28:$H$28,Assumptions!$C$50)*10*(1-Assumptions!$C$52)-INDEX('Debt_Schedule'!$D$33:$H$33,Assumptions!$C$50)+INDEX('Cash_Flow'!$D$17:$H$17,Assumptions!$C$50),0)/MAX(Assumptions!$C$28*8*(1+Assumptions!$C$8)-Sources_Uses!$C$9,1))^(1/MAX(Assumptions!$C$50,1))-1,"N/A") | G30: =IFERROR((MAX(INDEX('Assumptions'!$D$28:$H$28,Assumptions!$C$50)*11*(1-Assumptions!$C$52)-INDEX('Debt_Schedule'!$D$33:$H$33,Assumptions!$C$50)+INDEX('Cash_Flow'!$D$17:$H$17,Assumptions!$C$50),0)/MAX(Assumptions!$C$28*8*(1+Assumptions!$C$8)-Sources_Uses!$C$9,1))^(1/MAX(Assumptions!$C$50,1))-1,"N/A") | H30: =IFERROR((MAX(INDEX('Assumptions'!$D$28:$H$28,Assumptions!$C$50)*12*(1-Assumptions!$C$52)-INDEX('Debt_Schedule'!$D$33:$H$33,Assumptions!$C$50)+INDEX('Cash_Flow'!$D$17:$H$17,Assumptions!$C$50),0)/MAX(Assumptions!$C$28*8*(1+Assumptions!$C$8)-Sources_Uses!$C$9,1))^(1/MAX(Assumptions!$C$50,1))-1,"N/A") | I30: =IFERROR((MAX(INDEX('Assumptions'!$D$28:$H$28,Assumptions!$C$50)*13*(1-Assumptions!$C$52)-INDEX('Debt_Schedule'!$D$33:$H$33,Assumptions!$C$50)+INDEX('Cash_Flow'!$D$17:$H$17,Assumptions!$C$50),0)/MAX(Assumptions!$C$28*8*(1+Assumptions!$C$8)-Sources_Uses!$C$9,1))^(1/MAX(Assumptions!$C$50,1))-1,"N/A")
C31: 9 | D31: =IFERROR((MAX(INDEX('Assumptions'!$D$28:$H$28,Assumptions!$C$50)*8*(1-Assumptions!$C$52)-INDEX('Debt_Schedule'!$D$33:$H$33,Assumptions!$C$50)+INDEX('Cash_Flow'!$D$17:$H$17,Assumptions!$C$50),0)/MAX(Assumptions!$C$28*9*(1+Assumptions!$C$8)-Sources_Uses!$C$9,1))^(1/MAX(Assumptions!$C$50,1))-1,"N/A") | E31: =IFERROR((MAX(INDEX('Assumptions'!$D$28:$H$28,Assumptions!$C$50)*9*(1-Assumptions!$C$52)-INDEX('Debt_Schedule'!$D$33:$H$33,Assumptions!$C$50)+INDEX('Cash_Flow'!$D$17:$H$17,Assumptions!$C$50),0)/MAX(Assumptions!$C$28*9*(1+Assumptions!$C$8)-Sources_Uses!$C$9,1))^(1/MAX(Assumptions!$C$50,1))-1,"N/A") | F31: =IFERROR((MAX(INDEX('Assumptions'!$D$28:$H$28,Assumptions!$C$50)*10*(1-Assumptions!$C$52)-INDEX('Debt_Schedule'!$D$33:$H$33,Assumptions!$C$50)+INDEX('Cash_Flow'!$D$17:$H$17,Assumptions!$C$50),0)/MAX(Assumptions!$C$28*9*(1+Assumptions!$C$8)-Sources_Uses!$C$9,1))^(1/MAX(Assumptions!$C$50,1))-1,"N/A") | G31: =IFERROR((MAX(INDEX('Assumptions'!$D$28:$H$28,Assumptions!$C$50)*11*(1-Assumptions!$C$52)-INDEX('Debt_Schedule'!$D$33:$H$33,Assumptions!$C$50)+INDEX('Cash_Flow'!$D$17:$H$17,Assumptions!$C$50),0)/MAX(Assumptions!$C$28*9*(1+Assumptions!$C$8)-Sources_Uses!$C$9,1))^(1/MAX(Assumptions!$C$50,1))-1,"N/A") | H31: =IFERROR((MAX(INDEX('Assumptions'!$D$28:$H$28,Assumptions!$C$50)*12*(1-Assumptions!$C$52)-INDEX('Debt_Schedule'!$D$33:$H$33,Assumptions!$C$50)+INDEX('Cash_Flow'!$D$17:$H$17,Assumptions!$C$50),0)/MAX(Assumptions!$C$28*9*(1+Assumptions!$C$8)-Sources_Uses!$C$9,1))^(1/MAX(Assumptions!$C$50,1))-1,"N/A") | I31: =IFERROR((MAX(INDEX('Assumptions'!$D$28:$H$28,Assumptions!$C$50)*13*(1-Assumptions!$C$52)-INDEX('Debt_Schedule'!$D$33:$H$33,Assumptions!$C$50)+INDEX('Cash_Flow'!$D$17:$H$17,Assumptions!$C$50),0)/MAX(Assumptions!$C$28*9*(1+Assumptions!$C$8)-Sources_Uses!$C$9,1))^(1/MAX(Assumptions!$C$50,1))-1,"N/A")
C32: 10 | D32: =IFERROR((MAX(INDEX('Assumptions'!$D$28:$H$28,Assumptions!$C$50)*8*(1-Assumptions!$C$52)-INDEX('Debt_Schedule'!$D$33:$H$33,Assumptions!$C$50)+INDEX('Cash_Flow'!$D$17:$H$17,Assumptions!$C$50),0)/MAX(Assumptions!$C$28*10*(1+Assumptions!$C$8)-Sources_Uses!$C$9,1))^(1/MAX(Assumptions!$C$50,1))-1,"N/A") | E32: =IFERROR((MAX(INDEX('Assumptions'!$D$28:$H$28,Assumptions!$C$50)*9*(1-Assumptions!$C$52)-INDEX('Debt_Schedule'!$D$33:$H$33,Assumptions!$C$50)+INDEX('Cash_Flow'!$D$17:$H$17,Assumptions!$C$50),0)/MAX(Assumptions!$C$28*10*(1+Assumptions!$C$8)-Sources_Uses!$C$9,1))^(1/MAX(Assumptions!$C$50,1))-1,"N/A") | F32: =IFERROR((MAX(INDEX('Assumptions'!$D$28:$H$28,Assumptions!$C$50)*10*(1-Assumptions!$C$52)-INDEX('Debt_Schedule'!$D$33:$H$33,Assumptions!$C$50)+INDEX('Cash_Flow'!$D$17:$H$17,Assumptions!$C$50),0)/MAX(Assumptions!$C$28*10*(1+Assumptions!$C$8)-Sources_Uses!$C$9,1))^(1/MAX(Assumptions!$C$50,1))-1,"N/A") | G32: =IFERROR((MAX(INDEX('Assumptions'!$D$28:$H$28,Assumptions!$C$50)*11*(1-Assumptions!$C$52)-INDEX('Debt_Schedule'!$D$33:$H$33,Assumptions!$C$50)+INDEX('Cash_Flow'!$D$17:$H$17,Assumptions!$C$50),0)/MAX(Assumptions!$C$28*10*(1+Assumptions!$C$8)-Sources_Uses!$C$9,1))^(1/MAX(Assumptions!$C$50,1))-1,"N/A") | H32: =IFERROR((MAX(INDEX('Assumptions'!$D$28:$H$28,Assumptions!$C$50)*12*(1-Assumptions!$C$52)-INDEX('Debt_Schedule'!$D$33:$H$33,Assumptions!$C$50)+INDEX('Cash_Flow'!$D$17:$H$17,Assumptions!$C$50),0)/MAX(Assumptions!$C$28*10*(1+Assumptions!$C$8)-Sources_Uses!$C$9,1))^(1/MAX(Assumptions!$C$50,1))-1,"N/A") | I32: =IFERROR((MAX(INDEX('Assumptions'!$D$28:$H$28,Assumptions!$C$50)*13*(1-Assumptions!$C$52)-INDEX('Debt_Schedule'!$D$33:$H$33,Assumptions!$C$50)+INDEX('Cash_Flow'!$D$17:$H$17,Assumptions!$C$50),0)/MAX(Assumptions!$C$28*10*(1+Assumptions!$C$8)-Sources_Uses!$C$9,1))^(1/MAX(Assumptions!$C$50,1))-1,"N/A")
C33: 11 | D33: =IFERROR((MAX(INDEX('Assumptions'!$D$28:$H$28,Assumptions!$C$50)*8*(1-Assumptions!$C$52)-INDEX('Debt_Schedule'!$D$33:$H$33,Assumptions!$C$50)+INDEX('Cash_Flow'!$D$17:$H$17,Assumptions!$C$50),0)/MAX(Assumptions!$C$28*11*(1+Assumptions!$C$8)-Sources_Uses!$C$9,1))^(1/MAX(Assumptions!$C$50,1))-1,"N/A") | E33: =IFERROR((MAX(INDEX('Assumptions'!$D$28:$H$28,Assumptions!$C$50)*9*(1-Assumptions!$C$52)-INDEX('Debt_Schedule'!$D$33:$H$33,Assumptions!$C$50)+INDEX('Cash_Flow'!$D$17:$H$17,Assumptions!$C$50),0)/MAX(Assumptions!$C$28*11*(1+Assumptions!$C$8)-Sources_Uses!$C$9,1))^(1/MAX(Assumptions!$C$50,1))-1,"N/A") | F33: =IFERROR((MAX(INDEX('Assumptions'!$D$28:$H$28,Assumptions!$C$50)*10*(1-Assumptions!$C$52)-INDEX('Debt_Schedule'!$D$33:$H$33,Assumptions!$C$50)+INDEX('Cash_Flow'!$D$17:$H$17,Assumptions!$C$50),0)/MAX(Assumptions!$C$28*11*(1+Assumptions!$C$8)-Sources_Uses!$C$9,1))^(1/MAX(Assumptions!$C$50,1))-1,"N/A") | G33: =IFERROR((MAX(INDEX('Assumptions'!$D$28:$H$28,Assumptions!$C$50)*11*(1-Assumptions!$C$52)-INDEX('Debt_Schedule'!$D$33:$H$33,Assumptions!$C$50)+INDEX('Cash_Flow'!$D$17:$H$17,Assumptions!$C$50),0)/MAX(Assumptions!$C$28*11*(1+Assumptions!$C$8)-Sources_Uses!$C$9,1))^(1/MAX(Assumptions!$C$50,1))-1,"N/A") | H33: =IFERROR((MAX(INDEX('Assumptions'!$D$28:$H$28,Assumptions!$C$50)*12*(1-Assumptions!$C$52)-INDEX('Debt_Schedule'!$D$33:$H$33,Assumptions!$C$50)+INDEX('Cash_Flow'!$D$17:$H$17,Assumptions!$C$50),0)/MAX(Assumptions!$C$28*11*(1+Assumptions!$C$8)-Sources_Uses!$C$9,1))^(1/MAX(Assumptions!$C$50,1))-1,"N/A") | I33: =IFERROR((MAX(INDEX('Assumptions'!$D$28:$H$28,Assumptions!$C$50)*13*(1-Assumptions!$C$52)-INDEX('Debt_Schedule'!$D$33:$H$33,Assumptions!$C$50)+INDEX('Cash_Flow'!$D$17:$H$17,Assumptions!$C$50),0)/MAX(Assumptions!$C$28*11*(1+Assumptions!$C$8)-Sources_Uses!$C$9,1))^(1/MAX(Assumptions!$C$50,1))-1,"N/A")
C34: 12 | D34: =IFERROR((MAX(INDEX('Assumptions'!$D$28:$H$28,Assumptions!$C$50)*8*(1-Assumptions!$C$52)-INDEX('Debt_Schedule'!$D$33:$H$33,Assumptions!$C$50)+INDEX('Cash_Flow'!$D$17:$H$17,Assumptions!$C$50),0)/MAX(Assumptions!$C$28*12*(1+Assumptions!$C$8)-Sources_Uses!$C$9,1))^(1/MAX(Assumptions!$C$50,1))-1,"N/A") | E34: =IFERROR((MAX(INDEX('Assumptions'!$D$28:$H$28,Assumptions!$C$50)*9*(1-Assumptions!$C$52)-INDEX('Debt_Schedule'!$D$33:$H$33,Assumptions!$C$50)+INDEX('Cash_Flow'!$D$17:$H$17,Assumptions!$C$50),0)/MAX(Assumptions!$C$28*12*(1+Assumptions!$C$8)-Sources_Uses!$C$9,1))^(1/MAX(Assumptions!$C$50,1))-1,"N/A") | F34: =IFERROR((MAX(INDEX('Assumptions'!$D$28:$H$28,Assumptions!$C$50)*10*(1-Assumptions!$C$52)-INDEX('Debt_Schedule'!$D$33:$H$33,Assumptions!$C$50)+INDEX('Cash_Flow'!$D$17:$H$17,Assumptions!$C$50),0)/MAX(Assumptions!$C$28*12*(1+Assumptions!$C$8)-Sources_Uses!$C$9,1))^(1/MAX(Assumptions!$C$50,1))-1,"N/A") | G34: =IFERROR((MAX(INDEX('Assumptions'!$D$28:$H$28,Assumptions!$C$50)*11*(1-Assumptions!$C$52)-INDEX('Debt_Schedule'!$D$33:$H$33,Assumptions!$C$50)+INDEX('Cash_Flow'!$D$17:$H$17,Assumptions!$C$50),0)/MAX(Assumptions!$C$28*12*(1+Assumptions!$C$8)-Sources_Uses!$C$9,1))^(1/MAX(Assumptions!$C$50,1))-1,"N/A") | H34: =IFERROR((MAX(INDEX('Assumptions'!$D$28:$H$28,Assumptions!$C$50)*12*(1-Assumptions!$C$52)-INDEX('Debt_Schedule'!$D$33:$H$33,Assumptions!$C$50)+INDEX('Cash_Flow'!$D$17:$H$17,Assumptions!$C$50),0)/MAX(Assumptions!$C$28*12*(1+Assumptions!$C$8)-Sources_Uses!$C$9,1))^(1/MAX(Assumptions!$C$50,1))-1,"N/A") | I34: =IFERROR((MAX(INDEX('Assumptions'!$D$28:$H$28,Assumptions!$C$50)*13*(1-Assumptions!$C$52)-INDEX('Debt_Schedule'!$D$33:$H$33,Assumptions!$C$50)+INDEX('Cash_Flow'!$D$17:$H$17,Assumptions!$C$50),0)/MAX(Assumptions!$C$28*12*(1+Assumptions!$C$8)-Sources_Uses!$C$9,1))^(1/MAX(Assumptions!$C$50,1))-1,"N/A")
B40: MOIC SENSITIVITY (×) | Entry Multiple ↓ vs Exit Multiple →
B41: Debt held constant | Orange = base case | All else equal — only multiples vary
B42: Entry ↓ / Exit → | D42: 8 | E42: 9 | F42: 10 | G42: 11 | H42: 12 | I42: 13
C43: 8 | D43: =IFERROR(MAX(INDEX('Assumptions'!$D$28:$H$28,Assumptions!$C$50)*8*(1-Assumptions!$C$52)-INDEX('Debt_Schedule'!$D$33:$H$33,Assumptions!$C$50)+INDEX('Cash_Flow'!$D$17:$H$17,Assumptions!$C$50),0)/MAX(Assumptions!$C$28*8*(1+Assumptions!$C$8)-Sources_Uses!$C$9,1),0) | E43: =IFERROR(MAX(INDEX('Assumptions'!$D$28:$H$28,Assumptions!$C$50)*9*(1-Assumptions!$C$52)-INDEX('Debt_Schedule'!$D$33:$H$33,Assumptions!$C$50)+INDEX('Cash_Flow'!$D$17:$H$17,Assumptions!$C$50),0)/MAX(Assumptions!$C$28*8*(1+Assumptions!$C$8)-Sources_Uses!$C$9,1),0) | F43: =IFERROR(MAX(INDEX('Assumptions'!$D$28:$H$28,Assumptions!$C$50)*10*(1-Assumptions!$C$52)-INDEX('Debt_Schedule'!$D$33:$H$33,Assumptions!$C$50)+INDEX('Cash_Flow'!$D$17:$H$17,Assumptions!$C$50),0)/MAX(Assumptions!$C$28*8*(1+Assumptions!$C$8)-Sources_Uses!$C$9,1),0) | G43: =IFERROR(MAX(INDEX('Assumptions'!$D$28:$H$28,Assumptions!$C$50)*11*(1-Assumptions!$C$52)-INDEX('Debt_Schedule'!$D$33:$H$33,Assumptions!$C$50)+INDEX('Cash_Flow'!$D$17:$H$17,Assumptions!$C$50),0)/MAX(Assumptions!$C$28*8*(1+Assumptions!$C$8)-Sources_Uses!$C$9,1),0) | H43: =IFERROR(MAX(INDEX('Assumptions'!$D$28:$H$28,Assumptions!$C$50)*12*(1-Assumptions!$C$52)-INDEX('Debt_Schedule'!$D$33:$H$33,Assumptions!$C$50)+INDEX('Cash_Flow'!$D$17:$H$17,Assumptions!$C$50),0)/MAX(Assumptions!$C$28*8*(1+Assumptions!$C$8)-Sources_Uses!$C$9,1),0) | I43: =IFERROR(MAX(INDEX('Assumptions'!$D$28:$H$28,Assumptions!$C$50)*13*(1-Assumptions!$C$52)-INDEX('Debt_Schedule'!$D$33:$H$33,Assumptions!$C$50)+INDEX('Cash_Flow'!$D$17:$H$17,Assumptions!$C$50),0)/MAX(Assumptions!$C$28*8*(1+Assumptions!$C$8)-Sources_Uses!$C$9,1),0)
C44: 9 | D44: =IFERROR(MAX(INDEX('Assumptions'!$D$28:$H$28,Assumptions!$C$50)*8*(1-Assumptions!$C$52)-INDEX('Debt_Schedule'!$D$33:$H$33,Assumptions!$C$50)+INDEX('Cash_Flow'!$D$17:$H$17,Assumptions!$C$50),0)/MAX(Assumptions!$C$28*9*(1+Assumptions!$C$8)-Sources_Uses!$C$9,1),0) | E44: =IFERROR(MAX(INDEX('Assumptions'!$D$28:$H$28,Assumptions!$C$50)*9*(1-Assumptions!$C$52)-INDEX('Debt_Schedule'!$D$33:$H$33,Assumptions!$C$50)+INDEX('Cash_Flow'!$D$17:$H$17,Assumptions!$C$50),0)/MAX(Assumptions!$C$28*9*(1+Assumptions!$C$8)-Sources_Uses!$C$9,1),0) | F44: =IFERROR(MAX(INDEX('Assumptions'!$D$28:$H$28,Assumptions!$C$50)*10*(1-Assumptions!$C$52)-INDEX('Debt_Schedule'!$D$33:$H$33,Assumptions!$C$50)+INDEX('Cash_Flow'!$D$17:$H$17,Assumptions!$C$50),0)/MAX(Assumptions!$C$28*9*(1+Assumptions!$C$8)-Sources_Uses!$C$9,1),0) | G44: =IFERROR(MAX(INDEX('Assumptions'!$D$28:$H$28,Assumptions!$C$50)*11*(1-Assumptions!$C$52)-INDEX('Debt_Schedule'!$D$33:$H$33,Assumptions!$C$50)+INDEX('Cash_Flow'!$D$17:$H$17,Assumptions!$C$50),0)/MAX(Assumptions!$C$28*9*(1+Assumptions!$C$8)-Sources_Uses!$C$9,1),0) | H44: =IFERROR(MAX(INDEX('Assumptions'!$D$28:$H$28,Assumptions!$C$50)*12*(1-Assumptions!$C$52)-INDEX('Debt_Schedule'!$D$33:$H$33,Assumptions!$C$50)+INDEX('Cash_Flow'!$D$17:$H$17,Assumptions!$C$50),0)/MAX(Assumptions!$C$28*9*(1+Assumptions!$C$8)-Sources_Uses!$C$9,1),0) | I44: =IFERROR(MAX(INDEX('Assumptions'!$D$28:$H$28,Assumptions!$C$50)*13*(1-Assumptions!$C$52)-INDEX('Debt_Schedule'!$D$33:$H$33,Assumptions!$C$50)+INDEX('Cash_Flow'!$D$17:$H$17,Assumptions!$C$50),0)/MAX(Assumptions!$C$28*9*(1+Assumptions!$C$8)-Sources_Uses!$C$9,1),0)
C45: 10 | D45: =IFERROR(MAX(INDEX('Assumptions'!$D$28:$H$28,Assumptions!$C$50)*8*(1-Assumptions!$C$52)-INDEX('Debt_Schedule'!$D$33:$H$33,Assumptions!$C$50)+INDEX('Cash_Flow'!$D$17:$H$17,Assumptions!$C$50),0)/MAX(Assumptions!$C$28*10*(1+Assumptions!$C$8)-Sources_Uses!$C$9,1),0) | E45: =IFERROR(MAX(INDEX('Assumptions'!$D$28:$H$28,Assumptions!$C$50)*9*(1-Assumptions!$C$52)-INDEX('Debt_Schedule'!$D$33:$H$33,Assumptions!$C$50)+INDEX('Cash_Flow'!$D$17:$H$17,Assumptions!$C$50),0)/MAX(Assumptions!$C$28*10*(1+Assumptions!$C$8)-Sources_Uses!$C$9,1),0) | F45: =IFERROR(MAX(INDEX('Assumptions'!$D$28:$H$28,Assumptions!$C$50)*10*(1-Assumptions!$C$52)-INDEX('Debt_Schedule'!$D$33:$H$33,Assumptions!$C$50)+INDEX('Cash_Flow'!$D$17:$H$17,Assumptions!$C$50),0)/MAX(Assumptions!$C$28*10*(1+Assumptions!$C$8)-Sources_Uses!$C$9,1),0) | G45: =IFERROR(MAX(INDEX('Assumptions'!$D$28:$H$28,Assumptions!$C$50)*11*(1-Assumptions!$C$52)-INDEX('Debt_Schedule'!$D$33:$H$33,Assumptions!$C$50)+INDEX('Cash_Flow'!$D$17:$H$17,Assumptions!$C$50),0)/MAX(Assumptions!$C$28*10*(1+Assumptions!$C$8)-Sources_Uses!$C$9,1),0) | H45: =IFERROR(MAX(INDEX('Assumptions'!$D$28:$H$28,Assumptions!$C$50)*12*(1-Assumptions!$C$52)-INDEX('Debt_Schedule'!$D$33:$H$33,Assumptions!$C$50)+INDEX('Cash_Flow'!$D$17:$H$17,Assumptions!$C$50),0)/MAX(Assumptions!$C$28*10*(1+Assumptions!$C$8)-Sources_Uses!$C$9,1),0) | I45: =IFERROR(MAX(INDEX('Assumptions'!$D$28:$H$28,Assumptions!$C$50)*13*(1-Assumptions!$C$52)-INDEX('Debt_Schedule'!$D$33:$H$33,Assumptions!$C$50)+INDEX('Cash_Flow'!$D$17:$H$17,Assumptions!$C$50),0)/MAX(Assumptions!$C$28*10*(1+Assumptions!$C$8)-Sources_Uses!$C$9,1),0)
C46: 11 | D46: =IFERROR(MAX(INDEX('Assumptions'!$D$28:$H$28,Assumptions!$C$50)*8*(1-Assumptions!$C$52)-INDEX('Debt_Schedule'!$D$33:$H$33,Assumptions!$C$50)+INDEX('Cash_Flow'!$D$17:$H$17,Assumptions!$C$50),0)/MAX(Assumptions!$C$28*11*(1+Assumptions!$C$8)-Sources_Uses!$C$9,1),0) | E46: =IFERROR(MAX(INDEX('Assumptions'!$D$28:$H$28,Assumptions!$C$50)*9*(1-Assumptions!$C$52)-INDEX('Debt_Schedule'!$D$33:$H$33,Assumptions!$C$50)+INDEX('Cash_Flow'!$D$17:$H$17,Assumptions!$C$50),0)/MAX(Assumptions!$C$28*11*(1+Assumptions!$C$8)-Sources_Uses!$C$9,1),0) | F46: =IFERROR(MAX(INDEX('Assumptions'!$D$28:$H$28,Assumptions!$C$50)*10*(1-Assumptions!$C$52)-INDEX('Debt_Schedule'!$D$33:$H$33,Assumptions!$C$50)+INDEX('Cash_Flow'!$D$17:$H$17,Assumptions!$C$50),0)/MAX(Assumptions!$C$28*11*(1+Assumptions!$C$8)-Sources_Uses!$C$9,1),0) | G46: =IFERROR(MAX(INDEX('Assumptions'!$D$28:$H$28,Assumptions!$C$50)*11*(1-Assumptions!$C$52)-INDEX('Debt_Schedule'!$D$33:$H$33,Assumptions!$C$50)+INDEX('Cash_Flow'!$D$17:$H$17,Assumptions!$C$50),0)/MAX(Assumptions!$C$28*11*(1+Assumptions!$C$8)-Sources_Uses!$C$9,1),0) | H46: =IFERROR(MAX(INDEX('Assumptions'!$D$28:$H$28,Assumptions!$C$50)*12*(1-Assumptions!$C$52)-INDEX('Debt_Schedule'!$D$33:$H$33,Assumptions!$C$50)+INDEX('Cash_Flow'!$D$17:$H$17,Assumptions!$C$50),0)/MAX(Assumptions!$C$28*11*(1+Assumptions!$C$8)-Sources_Uses!$C$9,1),0) | I46: =IFERROR(MAX(INDEX('Assumptions'!$D$28:$H$28,Assumptions!$C$50)*13*(1-Assumptions!$C$52)-INDEX('Debt_Schedule'!$D$33:$H$33,Assumptions!$C$50)+INDEX('Cash_Flow'!$D$17:$H$17,Assumptions!$C$50),0)/MAX(Assumptions!$C$28*11*(1+Assumptions!$C$8)-Sources_Uses!$C$9,1),0)
C47: 12 | D47: =IFERROR(MAX(INDEX('Assumptions'!$D$28:$H$28,Assumptions!$C$50)*8*(1-Assumptions!$C$52)-INDEX('Debt_Schedule'!$D$33:$H$33,Assumptions!$C$50)+INDEX('Cash_Flow'!$D$17:$H$17,Assumptions!$C$50),0)/MAX(Assumptions!$C$28*12*(1+Assumptions!$C$8)-Sources_Uses!$C$9,1),0) | E47: =IFERROR(MAX(INDEX('Assumptions'!$D$28:$H$28,Assumptions!$C$50)*9*(1-Assumptions!$C$52)-INDEX('Debt_Schedule'!$D$33:$H$33,Assumptions!$C$50)+INDEX('Cash_Flow'!$D$17:$H$17,Assumptions!$C$50),0)/MAX(Assumptions!$C$28*12*(1+Assumptions!$C$8)-Sources_Uses!$C$9,1),0) | F47: =IFERROR(MAX(INDEX('Assumptions'!$D$28:$H$28,Assumptions!$C$50)*10*(1-Assumptions!$C$52)-INDEX('Debt_Schedule'!$D$33:$H$33,Assumptions!$C$50)+INDEX('Cash_Flow'!$D$17:$H$17,Assumptions!$C$50),0)/MAX(Assumptions!$C$28*12*(1+Assumptions!$C$8)-Sources_Uses!$C$9,1),0) | G47: =IFERROR(MAX(INDEX('Assumptions'!$D$28:$H$28,Assumptions!$C$50)*11*(1-Assumptions!$C$52)-INDEX('Debt_Schedule'!$D$33:$H$33,Assumptions!$C$50)+INDEX('Cash_Flow'!$D$17:$H$17,Assumptions!$C$50),0)/MAX(Assumptions!$C$28*12*(1+Assumptions!$C$8)-Sources_Uses!$C$9,1),0) | H47: =IFERROR(MAX(INDEX('Assumptions'!$D$28:$H$28,Assumptions!$C$50)*12*(1-Assumptions!$C$52)-INDEX('Debt_Schedule'!$D$33:$H$33,Assumptions!$C$50)+INDEX('Cash_Flow'!$D$17:$H$17,Assumptions!$C$50),0)/MAX(Assumptions!$C$28*12*(1+Assumptions!$C$8)-Sources_Uses!$C$9,1),0) | I47: =IFERROR(MAX(INDEX('Assumptions'!$D$28:$H$28,Assumptions!$C$50)*13*(1-Assumptions!$C$52)-INDEX('Debt_Schedule'!$D$33:$H$33,Assumptions!$C$50)+INDEX('Cash_Flow'!$D$17:$H$17,Assumptions!$C$50),0)/MAX(Assumptions!$C$28*12*(1+Assumptions!$C$8)-Sources_Uses!$C$9,1),0)
