Workbook
Name IQ_CH: 110000
Name IQ_CQ: 5000
Name IQ_CY: 10000
Name IQ_DAILY: 500000
Name IQ_FH: 100000
Name IQ_FQ: 500
Name IQ_FY: 1000
Name IQ_LTM: 2000
Name IQ_MONTH: 15000
Name IQ_NTM: 6000
Name IQ_WEEK: 50000
Name IQ_YTD: 3000

Sheet IS
A1: Ltd Income Statement
A2: All numbers are in £ millions except per share data
C4: 2021 | D4: =C4+1 -> 2022 | E4: =D4+1 -> 2023 | F4: =E4+1 -> 2024 | G4: =F4+1 -> 2025 | H4: =G4+1 -> 2026 | I4: =H4+1 -> 2027 | J4: =I4+1 -> 2028 | K4: =J4+1 -> 2029 | L4: =K4+1 -> 2030 | R4: 2021 | S4: =R4+1 -> 2022 | T4: =S4+1 -> 2023 | U4: =T4+1 -> 2024 | V4: =U4+1 -> 2025 | W4: =V4+1 -> 2026 | X4: =W4+1 -> 2027 | Y4: =X4+1 -> 2028 | Z4: =Y4+1 -> 2029
B5: Revenues | C5: 92175 | D5: 94163 | E5: 98282 | F5: 96855 | G5: 104210 | H5: =G5*(1+H27) -> 109420.5 | I5: =H5*(1+I27) -> 114891.53 | J5: =I5*(1+J27) -> 120636.1 | K5: =J5*(1+K27) -> 126667.91 | L5: =K5*(1+L27) -> 133001.3 | M5: = Last year Rev * (1+Rev Yoy) | Q5: Revenues | R5: 1000 | S5: 1100 | T5: 1200 | U5: 1300 | V5: 1450 | W5: =V5*(1+W9) -> 1595 | X5: =W5*(1+X9) -> 1754.5 | Y5: =X5*(1+Y9) -> 1929.95 | Z5: =Y5*(1+Z9) -> 2122.945 | AA5: =V5*(1+W9)
B6: Cost of sales | C6: -74043 | D6: -75442 | E6: -78329 | F6: -78477 | G6: -83000 | H6: =H28*H5 -> -87150 | I6: =I28*I5 -> -91507.5 | J6: =J28*J5 -> -96082.875 | K6: =K28*K5 -> -100887.02 | L6: =L28*L5 -> -105931.37 | M6: = COGS margin * Revenue | Q6: COGS | R6: 500 | S6: 550 | T6: 610 | U6: 650 | V6: 700 | W6: =W5*W10 -> 770 | X6: =X5*X10 -> 847 | Y6: =Y5*Y10 -> 931.7 | Z6: =Z5*Z10 -> 1024.87 | AA6: =W5*W10
B7: Gross profit | C7: =C5+C6 -> 18132 | D7: =D5+D6 -> 18721 | E7: =E5+E6 -> 19953 | F7: =F5+F6 -> 18378 | G7: =G5+G6 -> 21210 | H7: =H5+H6 -> 22270.5 | I7: =I5+I6 -> 23384.025 | J7: =J5+J6 -> 24553.226 | ... L7: =L5+L6 -> 27069.932 | M7: = Revenues * Cost of Sales | Q7: Gross profit | R7: =R5-R6 -> 500 | S7: =S5-S6 -> 550 | T7: =T5-T6 -> 590 | U7: =U5-U6 -> 650 | V7: =V5-V6 -> 750 | W7: =W5-W6 -> 825 | X7: =X5-X6 -> 907.5 | Y7: =Y5-Y6 -> 998.25 | Z7: =Z5-Z6 -> 1098.075 | AA7: =W5-W6
B8: Selling and administrative expenses | C8: -3633 | D8: -3600 | E8: -3700 | F8: -3800 | G8: -4000 | H8: =H29*H5 -> -4200 | I8: =I29*I5 -> -4410 | J8: =J29*J5 -> -4630.5 | K8: =K29*K5 -> -4862.025 | L8: =L29*L5 -> -5105.1263 | M8: = SG&A margin * Revenue
B9: Other operating income | C9: 914 | D9: 670 | E9: 720 | F9: 774 | G9: 1031 | H9: =H30*H5 -> 1082.55 | I9: =I30*I5 -> 1136.6775 | J9: =J30*J5 -> 1193.5114 | K9: =K30*K5 -> 1253.1869 | L9: =L30*L5 -> 1315.8463 | M9: = Other income margin * Revenue | Q9: Revenue YoY | S9: =S5/R5-1 -> 0.1 | T9: =T5/S5-1 -> 0.090909091 | U9: =U5/T5-1 -> 0.083333333 | V9: =V5/U5-1 -> 0.11538462 | W9: 0.1 | X9: 0.1 | Y9: 0.1 | Z9: 0.1 | AB9: Averages for revenue growth in the real world
B10: Other operating expenses | C10: -820 | D10: -847 | E10: -1214 | F10: -651 | G10: -2316 | H10: =H31*H5 -> -2431.8 | I10: =I31*I5 -> -2553.39 | J10: =J31*J5 -> -2681.0595 | K10: =K31*K5 -> -2815.1125 | L10: =L31*L5 -> -2955.8681 | M10: = Other operating margin * Revenue | Q10: COGS margin | R10: =R6/R5 -> 0.5 | S10: =S6/S5 -> 0.5 | T10: =T6/T5 -> 0.50833333 | U10: =U6/U5 -> 0.5 | V10: =V6/V5 -> 0.48275862 | W10: =V10 -> 0.48275862 | X10: =W10 -> 0.48275862 | Y10: =X10 -> 0.48275862 | Z10: =Y10 -> 0.48275862 | AB10: Typically all of the expenses on the income statement is forecasted using margins
B11: EBITDA | C11: =SUM(C7:C10) -> 14593 | D11: =SUM(D7:D10) -> 14944 | E11: =SUM(E7:E10) -> 15759 | F11: =SUM(F7:F10) -> 14701 | G11: =SUM(G7:G10) -> 15925 | H11: =SUM(H7:H10) -> 16721.25 | I11: =SUM(I7:I10) -> 17557.313 | J11: =SUM(J7:J10) -> 18435.178 | ... L11: =SUM(L7:L10) -> 20324.784 | M11: = GP + S&A Exp + op. inc. + op. exp.
B12: D&A | C12: -3000 | D12: =BS!D70+BS!D79 -> -4215 | E12: =BS!E70+BS!E79 -> -5193 | F12: =BS!F70+BS!F79 -> -6493 | G12: =BS!G70+BS!G79 -> -8242 | H12: =BS!H70+BS!H79 -> -8744.7255 | I12: =BS!I70+BS!I79 -> -9246.882 | J12: =BS!J70+BS!J79 -> -9756.8456 | K12: =BS!K70+BS!K79 -> -10280.57 | L12: =BS!L70+BS!L79 -> -10822.432 | M12: = Ammortization + Depreciation from BS
B13: EBIT | C13: =C11+C12 -> 11593 | D13: =D11+D12 -> 10729 | E13: =E11+E12 -> 10566 | F13: =F11+F12 -> 8208 | G13: =G11+G12 -> 7683 | H13: =SUM(H11:H12) -> 7976.5245 | I13: =SUM(I11:I12) -> 8310.4305 | J13: =SUM(J11:J12) -> 8678.3325 | K13: =SUM(K11:K12) -> 9076.3674 | L13: =SUM(L11:L12) -> 9502.3524 | M13: = EBITDA + D&A | R13: Colour Code
B14: Interest and similar income | C14: 185 | D14: 196 | E14: 201 | F14: 397 | G14: 179 | H14: =H41 -> 196.23317 | I14: =I41 -> 247.2522 | J14: =J41 -> 297.21201 | K14: =K41 -> 345.892 | L14: =L41 -> 393.10745 | M14: =H41 | R14: Type | U14: Text colour
B15: Interest and similar expenses | C15: -618 | D15: -489 | E15: -412 | F15: -386 | G15: -499 | H15: =H37 -> -627 | I15: =I37 -> -740 | J15: =J37 -> -852 | K15: =K37 -> -965 | L15: =L37 -> -1078 | M15: = H37 | R15: Hardcoded | U15: Blue
B16: Profit / loss before tax | C16: =C13+C14+C15 -> 11160 | D16: =D13+D14+D15 -> 10436 | E16: =E13+E14+E15 -> 10355 | F16: =F13+F14+F15 -> 8219 | G16: =G13+G14+G15 -> 7363 | H16: =SUM(H13:H15) -> 7545.7577 | I16: =SUM(I13:I15) -> 7817.6827 | J16: =SUM(J13:J15) -> 8123.5446 | K16: =SUM(K13:K15) -> 8457.2594 | L16: =SUM(L13:L15) -> 8817.4598 | M16: = EBIT + Int. & similar income + Int. & similar expenses | R16: Formula | U16: Black
B17: Income taxes | C17: =(0.32*C16)/-1 -> -3571.2 | D17: =(0.3*D16)/-1 -> -3130.8 | E17: =(0.28*E16)/-1 -> -2899.4 | F17: =(0.32*F16)/-1 -> -2630.08 | G17: =(0.31*G16)/-1 -> -2282.53 | H17: =H16*H44 -> -2339.1849 | I17: =I16*I44 -> -2423.4816 | J17: =J16*J44 -> -2518.2988 | K17: =K16*K44 -> -2621.7504 | L17: =L16*L44 -> -2733.4125 | M17: = Profit/Loss before tax * Income Tax Rate | R17: Link from another sheet | U17: Green
B18: Net profit / loss | C18: =C16+C17 -> 7588.8 | D18: =D16+D17 -> 7305.2 | E18: =E16+E17 -> 7455.6 | F18: =F16+F17 -> 5588.92 | G18: =G16+G17 -> 5080.47 | H18: =SUM(H16:H17) -> 5206.5728 | I18: =SUM(I16:I17) -> 5394.201 | J18: =SUM(J16:J17) -> 5605.2457 | K18: =SUM(K16:K17) -> 5835.509 | L18: =SUM(L16:L17) -> 6084.0473 | M18: = Profit/Loss before tax + Income taxes | R18: Link from the same sheet | U18: Pink or black
B20: Number of shares outstanding | C20: 5000 | D20: 5100 | E20: =D20+100 -> 5200 | F20: =E20+100 -> 5300 | G20: =F20+100 -> 5400 | H20: =G20+100 -> 5500 | I20: =H20+100 -> 5600 | J20: =I20+100 -> 5700 | K20: =J20+100 -> 5800 | L20: =K20+100 -> 5900 | M20: = Assuming share count increment is 100 every year
B21: EPS (Earnings per share) | C21: =C18/C20 -> 1.51776 | D21: =D18/D20 -> 1.4323922 | E21: =E18/E20 -> 1.4337692 | F21: =F18/F20 -> 1.0545132 | G21: =G18/G20 -> 0.94082778 | H21: =H18/H20 -> 0.9466496 | I21: =I18/I20 -> 0.96325019 | J21: =J18/J20 -> 0.98337645 | ... L21: =L18/L20 -> 1.0311945 | M21: = Net profit or loss / Number of shares outstanding
B23: Dividends | C23: 3794.4 | D23: 3652.6 | E23: 3727.8 | F23: 2794.46 | G23: 2540.235 | H23: =H24*H18 -> 2603.2864 | I23: =I24*I18 -> 2697.1005 | J23: =J24*J18 -> 2802.6229 | K23: =K24*K18 -> 2917.7545 | L23: =L24*L18 -> 3042.0236 | M23: = Dividend payout ratio * Net profit/loss
B24: Dividend payout ratio | C24: =C23/C18 -> 0.5 | D24: =D23/D18 -> 0.5 | E24: =E23/E18 -> 0.5 | F24: =F23/F18 -> 0.5 | G24: =G23/G18 -> 0.5 | H24: =G23/G18 -> 0.5 | I24: =G23/G18 -> 0.5 | J24: =G23/G18 -> 0.5 | K24: =G23/G18 -> 0.5 | L24: =G23/G18 -> 0.5
B26: Ratios and Assumptions
B27: Revenue YoY | D27: =D5/C5-1 -> 0.02156767 | E27: =E5/D5-1 -> 0.043743296 | F27: =F5/E5-1 -> -0.014519444 | G27: =G5/F5-1 -> 0.075938258 | H27: 0.05 | I27: 0.05 | J27: 0.05 | K27: 0.05 | L27: 0.05 | M27: =(Rev year 2/Rev year 1) -1
B28: COGS margin | C28: =C6/C5 -> -0.80328723 | D28: =D6/D5 -> -0.80118518 | E28: =E6/E5 -> -0.79698215 | F28: =F6/F5 -> -0.81025244 | G28: =G6/G5 -> -0.79646867 | H28: =G28 -> -0.79646867 | I28: =H28 -> -0.79646867 | J28: =I28 -> -0.79646867 | K28: =J28 -> -0.79646867 | L28: =K28 -> -0.79646867 | M28: =Cost of Sales / Revenue
B29: SG&A margin | C29: =C8/C5 -> -0.039414158 | D29: =D8/D5 -> -0.038231577 | E29: =E8/E5 -> -0.037646772 | F29: =F8/F5 -> -0.039233906 | G29: =G8/G5 -> -0.038384032 | H29: =G29 -> -0.038384032 | I29: =H29 -> -0.038384032 | J29: =I29 -> -0.038384032 | K29: =J29 -> -0.038384032 | L29: =K29 -> -0.038384032 | M29: = SG&A expenses / Revenue
B30: Other income margin | C30: =C9/C5 -> 0.0099159208 | D30: =D9/D5 -> 0.0071153213 | E30: =E9/E5 -> 0.0073258582 | F30: =F9/F5 -> 0.0079913272 | G30: =G9/G5 -> 0.0098934843 | H30: =G30 -> 0.0098934843 | I30: =H30 -> 0.0098934843 | J30: =I30 -> 0.0098934843 | K30: =J30 -> 0.0098934843 | L30: =K30 -> 0.0098934843 | M30: = Other operating income / Revenue
B31: Other expense margin | C31: =C10/C5 -> -0.0088961215 | D31: =D10/D5 -> -0.0089950405 | E31: =E10/E5 -> -0.012352211 | F31: =F10/F5 -> -0.0067213876 | G31: =G10/G5 -> -0.022224355 | H31: =G31 -> -0.022224355 | I31: =H31 -> -0.022224355 | J31: =I31 -> -0.022224355 | K31: =J31 -> -0.022224355 | L31: =K31 -> -0.022224355 | M31: = Other operating expenses / Revenue
B32: D&A margin
B34: LT Debt | C34: =BS!C89 -> 10895 | D34: =BS!D89 -> 10081 | E34: =BS!E89 -> 10562 | F34: =BS!F89 -> 17129 | G34: =BS!G89 -> 21805 | H34: =BS!H89 -> 25805 | I34: =BS!I89 -> 29805 | J34: =BS!J89 -> 33805 | ... L34: =BS!L89 -> 41805 | M34: = both LT and ST from BS
B35: ST Debt | C35: =BS!C95 -> 4000 | D35: =BS!D95 -> 5000 | E35: =BS!E95 -> 6000 | F35: =BS!F95 -> 5000 | G35: =BS!G95 -> 6000 | H35: =BS!H95 -> 7000 | I35: =BS!I95 -> 8000 | J35: =BS!J95 -> 9000 | ... L35: =BS!L95 -> 11000
B36: Total Debt | C36: =SUM(C34:C35) -> 14895 | D36: =SUM(D34:D35) -> 15081 | E36: =SUM(E34:E35) -> 16562 | F36: =SUM(F34:F35) -> 22129 | G36: =SUM(G34:G35) -> 27805 | H36: =SUM(H34:H35) -> 32805 | I36: =SUM(I34:I35) -> 37805 | J36: =SUM(J34:J35) -> 42805 | ... L36: =SUM(L34:L35) -> 52805 | M36: = LT Debt + ST Debt
B37: Interest expense | C37: =C15 -> -618 | D37: =D15 -> -489 | E37: =E15 -> -412 | F37: =F15 -> -386 | G37: =G15 -> -499 | H37: =-627 -> -627 | I37: =-740 -> -740 | J37: =-852 -> -852 | K37: =-965 -> -965 | L37: =-1078 -> -1078 | M37: = Interest expense rate year 2 * Total Debt year 1
B38: Interest expense rate | D38: =D37/C36 -> -0.032829809 | E38: =E37/D36 -> -0.027319143 | F38: =F37/E36 -> -0.023306364 | G38: =G37/F36 -> -0.022549596 | H38: -0.023 | I38: -0.023 | J38: -0.023 | K38: -0.023 | L38: -0.023 | M38: = Interest expense year 2 / Total Debt year 1
B40: Cash and cash equivalents | C40: =BS!C15 -> 6122 | D40: =BS!D15 -> 7880 | E40: =BS!E15 -> 9039 | F40: =BS!F15 -> 10979 | G40: =BS!G15 -> 12036 | H40: =BS!H15 -> 15165.262 | I40: =BS!I15 -> 18229.557 | J40: =BS!J15 -> 21215.353 | ... L40: =BS!L15 -> 26908.304 | M40: = BS!C15
B41: Interest income | C41: =C14 -> 185 | D41: =D14 -> 196 | E41: =E14 -> 201 | F41: =F14 -> 397 | G41: =G14 -> 179 | H41: =H42*G40 -> 196.23317 | I41: =I42*H40 -> 247.2522 | J41: =J42*I40 -> 297.21201 | K41: =K42*J40 -> 345.892 | L41: =L42*K40 -> 393.10745
B42: Interest income rate | D42: =D41/C40 -> 0.032015681 | E42: =E41/D40 -> 0.025507614 | F42: =F41/E40 -> 0.043920788 | G42: =G41/F40 -> 0.016303853 | H42: =G41/F40 -> 0.016303853 | I42: =G41/F40 -> 0.016303853 | J42: =G41/F40 -> 0.016303853 | K42: =G41/F40 -> 0.016303853 | L42: =G41/F40 -> 0.016303853
B44: Income tax rate | C44: =C17/C16 -> -0.32 | D44: =D17/D16 -> -0.3 | E44: =E17/E16 -> -0.28 | F44: =F17/F16 -> -0.32 | G44: =G17/G16 -> -0.31 | H44: -0.31 | I44: -0.31 | J44: -0.31 | K44: -0.31 | L44: -0.31 | M44: = Income taxes / Profit or loss before tax

Sheet BS
A1: Ltd Balance Sheet
A2: =IS!A2 -> All numbers are in £ millions except per share data
C5: 2021 | D5: =C5+1 -> 2022 | E5: =D5+1 -> 2023 | F5: =E5+1 -> 2024 | G5: =F5+1 -> 2025 | H5: =G5+1 -> 2026 | I5: =H5+1 -> 2027 | J5: =I5+1 -> 2028 | K5: =J5+1 -> 2029 | L5: =K5+1 -> 2030
B6: Assets
B7: Intangible assets | C7: 7372 | D7: 8157 | E7: 9464 | F7: 10971 | G7: 11729 | H7: =H71 -> 12453.461 | I7: =I71 -> 13167.071 | J7: =J71 -> 13885.346 | K7: =K71 -> 14619.096 | L7: =L71 -> 15376.066 | M7: = H71 = Ending Intangibles
B8: Property, plant and equipment | C8: 50000 | D8: 55000 | E8: 60000 | F8: 64500 | G8: 68000 | H8: =H80 -> 71655.814 | I8: =I80 -> 75476.571 | J8: =J80 -> 79471.764 | K8: =K80 -> 83651.272 | L8: =L80 -> 88025.389 | M8: = H80 = Ending PP&E
B9: Deferred tax | C9: 1945 | D9: 2327 | E9: 1993 | F9: 1638 | G9: 2194 | H9: =G9 -> 2194 | I9: =H9 -> 2194 | J9: =I9 -> 2194 | K9: =J9 -> 2194 | L9: =K9 -> 2194 | M9: = SL
B10: Other assets | C10: 2749 | D10: 1636 | E10: 1516 | F10: 2185 | G10: 2488 | H10: =G10 -> 2488 | I10: =H10 -> 2488 | J10: =I10 -> 2488 | K10: =J10 -> 2488 | L10: =K10 -> 2488 | M10: = SL
B11: Non-current assets | C11: =SUM(C7:C10) -> 62066 | D11: =SUM(D7:D10) -> 67120 | E11: =SUM(E7:E10) -> 72973 | F11: =SUM(F7:F10) -> 79294 | G11: =SUM(G7:G10) -> 84411 | H11: =SUM(H7:H10) -> 88791.275 | I11: =SUM(I7:I10) -> 93325.643 | J11: =SUM(J7:J10) -> 98039.109 | ... L11: =SUM(L7:L10) -> 108083.46 | M11: = Assets (sum all)
B12: Inventories | C12: 11071 | D12: 11841 | E12: 12707 | F12: 14248 | G12: 15891 | H12: =H42 -> 16685.55 | I12: =I42 -> 17519.827 | J12: =J42 -> 18395.819 | K12: =K42 -> 19315.61 | L12: =L42 -> 20281.39 | M12: = H42
B13: Trade receivables | C13: 2751 | D13: 2825 | E13: 2667 | F13: 2546 | G13: 2518 | H13: =H43 -> 2643.9 | I13: =I43 -> 2776.095 | J13: =J43 -> 2914.8998 | K13: =K43 -> 3060.6447 | L13: =L43 -> 3213.677 | M13: = H43
B14: Other assets | C14: 4693 | D14: 5087 | E14: 7485 | F14: 9749 | G14: 11614 | H14: =H44 -> 12194.7 | I14: =I44 -> 12804.435 | J14: =J44 -> 13444.657 | K14: =K44 -> 14116.89 | L14: =L44 -> 14822.734 | M14: = H44
B15: Cash and cash equivalents | C15: 6122 | D15: 7880 | E15: 9039 | F15: 10979 | G15: 12036 | H15: =CF!H34 -> 15165.262 | I15: =CF!I34 -> 18229.557 | J15: =CF!J34 -> 21215.353 | K15: =CF!K34 -> 24111.322 | L15: =CF!L34 -> 26908.304 | M15: =CF!H34
B16: Current Assets | C16: =SUM(C12,C13:C15) -> 24637 | D16: =SUM(D12:D15) -> 27633 | E16: =SUM(E12:E15) -> 31898 | F16: =SUM(F12:F15) -> 37522 | G16: =SUM(G12:G15) -> 42059 | H16: =SUM(H12:H15) -> 46689.412 | I16: =SUM(I12:I15) -> 51329.914 | J16: =SUM(J12:J15) -> 55970.729 | K16: =SUM(K12:K15) -> 60604.466 | L16: =SUM(L12:L15) -> 65226.105 | M16: = Sum (Inventories : Cash and cash equivalents)
B18: Total Assets | C18: =C16+C11 -> 86703 | D18: =D16+D11 -> 94753 | E18: =E16+E11 -> 104871 | F18: =F16+F11 -> 116816 | G18: =G16+G11 -> 126470 | H18: =H16+H11 -> 135480.69 | I18: =I16+I11 -> 144655.56 | J18: =J16+J11 -> 154009.84 | ... L18: =L16+L11 -> 173309.56 | M18: = Non-current assets + Current Assets
B20: Equity and liabilities
B21: Subscribed capital | C21: 657 | D21: 657 | E21: 658 | F21: 658 | G21: 659 | H21: =G21 -> 659 | I21: =H21 -> 659 | J21: =I21 -> 659 | K21: =J21 -> 659 | L21: =K21 -> 659 | M21: = SL
B22: Capital reserves | C22: 2027 | D22: 2047 | E22: 2084 | F22: 2118 | G22: 2161 | H22: =G22 -> 2161 | I22: =H22 -> 2161 | J22: =I22 -> 2161 | K22: =J22 -> 2161 | L22: =K22 -> 2161 | M22: = SL
B23: Retained Earnings | C23: 41027 | D23: 44445 | E23: 50815 | F23: 55862 | G23: 57667 | H23: =G23+IS!H18-IS!H23 -> 60270.286 | I23: =H23+IS!I18-IS!I23 -> 62967.387 | J23: =I23+IS!J18-IS!J23 -> 65770.01 | K23: =J23+IS!K18-IS!K23 -> 68687.764 | L23: =K23+IS!L18-IS!L23 -> 71729.788 | M23: = Retained Earnings prev. year + Net Profit or loss - Dividends
B24: Equity | C24: =SUM(C21:C23) -> 43711 | D24: =SUM(D21:D23) -> 47149 | E24: =SUM(E21:E23) -> 53557 | F24: =SUM(F21:F23) -> 58638 | G24: =SUM(G21:G23) -> 60487 | H24: =SUM(H21:H23) -> 63090.286 | I24: =SUM(I21:I23) -> 65787.387 | J24: =SUM(J21:J23) -> 68590.01 | ... L24: =SUM(L21:L23) -> 74549.788 | M24: = Sum all Equities and liabilities
B25: Pension provisions | C25: 3000 | D25: 4587 | E25: 3252 | F25: 2330 | G25: 3335 | H25: =G25 -> 3335 | I25: =H25 -> 3335 | J25: =I25 -> 3335 | K25: =J25 -> 3335 | L25: =K25 -> 3335 | M25: = SL
B26: Deferred tax | C26: 2116 | D26: 2795 | E26: 2157 | F26: 1773 | G26: 632 | H26: =G26 -> 632 | I26: =H26 -> 632 | J26: =I26 -> 632 | K26: =J26 -> 632 | L26: =K26 -> 632 | M26: = SL
B27: Long Term Debt | C27: 10895 | D27: 10081 | E27: 10562 | F27: 17129 | G27: 21805 | H27: =H89 -> 25805 | I27: =I89 -> 29805 | J27: =J89 -> 33805 | K27: =K89 -> 37805 | L27: =L89 -> 41805 | M27: = H89 = Ending LT Debt
B28: Other liabilities | C28: 4559 | D28: 5357 | E28: 5045 | F28: 5293 | G28: 5100 | H28: =G28 -> 5100 | I28: =H28 -> 5100 | J28: =I28 -> 5100 | K28: =J28 -> 5100 | L28: =K28 -> 5100 | M28: = SL
B29: Non-current provisions and liabilities | C29: =SUM(C25:C28) -> 20570 | D29: =SUM(D25:D28) -> 22820 | E29: =SUM(E25:E28) -> 21016 | F29: =SUM(F25:F28) -> 26525 | G29: =SUM(G25:G28) -> 30872 | H29: =SUM(H25:H28) -> 34872 | I29: =SUM(I25:I28) -> 38872 | J29: =SUM(J25:J28) -> 42872 | ... L29: =SUM(L25:L28) -> 50872 | M29: = Pension provisions + Deferred tax + LT Debt + Other liabilities
B30: Current tax | C30: 1441 | D30: 1074 | E30: 1124 | F30: 1158 | G30: 963 | H30: =G30 -> 963 | I30: =H30 -> 963 | J30: =I30 -> 963 | K30: =J30 -> 963 | L30: =K30 -> 963 | M30: = SL
B31: Short term debt | C31: 4000 | D31: 5000 | E31: 6000 | F31: 5000 | G31: 6000 | H31: =H95 -> 7000 | I31: =I95 -> 8000 | J31: =J95 -> 9000 | K31: =K95 -> 10000 | L31: =L95 -> 11000 | M31: = H95 = Ending ST Debt
B32: Trade payables | C32: 7773 | D32: 8512 | E32: 9731 | F32: 9669 | G32: 10182 | H32: =H46 -> 10691.1 | I32: =I46 -> 11225.655 | J32: =J46 -> 11786.938 | K32: =K46 -> 12376.285 | L32: =L46 -> 12995.099 | M32: = H46
B33: Other liabilities | C33: 9208 | D33: 10198 | E33: 13443 | F33: 15826 | G33: 17966 | H33: =H47 -> 18864.3 | I33: =I47 -> 19807.515 | J33: =J47 -> 20797.891 | K33: =K47 -> 21837.785 | L33: =L47 -> 22929.675 | M33: = H47
B34: Current provisions and liabilities | C34: =SUM(C30:C33) -> 22422 | D34: =SUM(D30:D33) -> 24784 | E34: =SUM(E30:E33) -> 30298 | F34: =SUM(F30:F33) -> 31653 | G34: =SUM(G30:G33) -> 35111 | H34: =SUM(H30:H33) -> 37518.4 | I34: =SUM(I30:I33) -> 39996.17 | J34: =SUM(J30:J33) -> 42547.829 | ... L34: =SUM(L30:L33) -> 47887.773 | M34: = Current tax + ST Debt + Trade payables + Other liabilities
B36: Total equity and liabilities | C36: =SUM(C34,C29,C24,) -> 86703 | D36: =SUM(D34,D29,D24,) -> 94753 | E36: =SUM(E34,E29,E24,) -> 104871 | F36: =SUM(F34,F29,F24,) -> 116816 | G36: =SUM(G34,G29,G24,) -> 126470 | H36: =SUM(H34,H29,H24,) -> 135480.69 | I36: =SUM(I34,I29,I24,) -> 144655.56 | J36: =SUM(J34,J29,J24,) -> 154009.84 | ... L36: =SUM(L34,L29,L24,) -> 173309.56 | M36: = Equity + Non-current provisions and liabilities + Current provision and liabilites
B38: check | C38: =C18-C36 -> 0 | D38: =D18-D36 -> 0 | E38: =E18-E36 -> 0 | F38: =F18-F36 -> 0 | G38: =G18-G36 -> 0 | H38: =H18-H36 -> 0 | I38: =I18-I36 -> 0 | J38: =J18-J36 -> 0 | ... L38: =L18-L36 -> 0
B40: Ratios and Assumptions
B41: Working capital
B42: =B12 -> Inventories | C42: =C12 -> 11071 | D42: =D12 -> 11841 | E42: =E12 -> 12707 | F42: =F12 -> 14248 | G42: =G12 -> 15891 | H42: =H52*H55 -> 16685.55 | I42: =I52*I55 -> 17519.827 | J42: =J52*J55 -> 18395.819 | K42: =K52*K55 -> 19315.61 | L42: =L52*L55 -> 20281.39 | M42: = Cost of Sales * Inventories as a % of COGS
B43: =B13 -> Trade receivables | C43: =C13 -> 2751 | D43: =D13 -> 2825 | E43: =E13 -> 2667 | F43: =F13 -> 2546 | G43: =G13 -> 2518 | H43: =H51*H56 -> 2643.9 | I43: =I51*I56 -> 2776.095 | J43: =J51*J56 -> 2914.8998 | K43: =K51*K56 -> 3060.6447 | L43: =L51*L56 -> 3213.677 | M43: = Revenue * Trade receivables as a % of revenue
B44: =B14 -> Other assets | C44: =C14 -> 4693 | D44: =D14 -> 5087 | E44: =E14 -> 7485 | F44: =F14 -> 9749 | G44: =G14 -> 11614 | H44: =H51*H57 -> 12194.7 | I44: =I51*I57 -> 12804.435 | J44: =J51*J57 -> 13444.657 | K44: =K51*K57 -> 14116.89 | L44: =L51*L57 -> 14822.734 | M44: = Revenue * Other assets as a % or revenue
B46: =B32 -> Trade payables | C46: =C32 -> 7773 | D46: =D32 -> 8512 | E46: =E32 -> 9731 | F46: =F32 -> 9669 | G46: =G32 -> 10182 | H46: =H52*H59 -> 10691.1 | I46: =I52*I59 -> 11225.655 | J46: =J52*J59 -> 11786.938 | K46: =K52*K59 -> 12376.285 | L46: =L52*L59 -> 12995.099 | M46: = Cost of Sales*Trade payables as a % of COGS
B47: =B33 -> Other liabilities | C47: =C33 -> 9208 | D47: =D33 -> 10198 | E47: =E33 -> 13443 | F47: =F33 -> 15826 | G47: =G33 -> 17966 | H47: =H60*H51 -> 18864.3 | I47: =I60*I51 -> 19807.515 | J47: =J60*J51 -> 20797.891 | K47: =K60*K51 -> 21837.785 | L47: =L60*L51 -> 22929.675 | M47: = Other liabilities as a % of revenue * Revenues
B48: Working capital | C48: =SUM(C42:C44)-SUM(C46:C47) -> 1534 | D48: =SUM(D42:D44)-SUM(D46:D47) -> 1043 | E48: =SUM(E42:E44)-SUM(E46:E47) -> -315 | F48: =SUM(F42:F44)-SUM(F46:F47) -> 1048 | G48: =SUM(G42:G44)-SUM(G46:G47) -> 1875 | H48: =SUM(H42:H44)-SUM(H46:H47) -> 1968.75 | I48: =SUM(I42:I44)-SUM(I46:I47) -> 2067.1875 | J48: =SUM(J42:J44)-SUM(J46:J47) -> 2170.5469 | ... L48: =SUM(L42:L44)-SUM(L46:L47) -> 2393.0279
...

Sheet CF
A1: Limited Cash flow statement
A2: All numbers in € million except for per share data
C4: 2021 | D4: =C4+1 -> 2022 | E4: =D4+1 -> 2023 | F4: =E4+1 -> 2024 | G4: =F4+1 -> 2025 | H4: =G4+1 -> 2026 | I4: =H4+1 -> 2027 | J4: =I4+1 -> 2028 | K4: =J4+1 -> 2029 | L4: =K4+1 -> 2030
B5: Net profit | H5: =IS!H18 -> 5206.5728 | I5: =IS!I18 -> 5394.201 | J5: =IS!J18 -> 5605.2457 | K5: =IS!K18 -> 5835.509 | L5: =IS!L18 -> 6084.0473 | M5: = From IS
B6: Other interest and similar income / expenses 1 | H6: =-SUM(IS!H14:H15) -> 430.76683 | I6: =-SUM(IS!I14:I15) -> 492.7478 | J6: =-SUM(IS!J14:J15) -> 554.78799 | K6: =-SUM(IS!K14:K15) -> 619.108 | L6: =-SUM(IS!L14:L15) -> 684.89255 | M6: = Interest and similar income + Interest and similar expenses (from IS)
B7: Depreciation and amortisation of tangible, intangible and investment assets | H7: =-IS!H12 -> 8744.7255 | I7: =-IS!I12 -> 9246.882 | J7: =-IS!J12 -> 9756.8456 | K7: =-IS!K12 -> 10280.57 | L7: =-IS!L12 -> 10822.432 | M7: = - D&A
B8: Change in provisions
B9: Change in deferred taxes | T9: CFO
B10: Changes in working capital | T10: CFI
B11: Change in inventories | H11: =BS!G42-BS!H42 -> -794.55 | I11: =BS!H42-BS!I42 -> -834.2775 | J11: =BS!I42-BS!J42 -> -875.99138 | K11: =BS!J42-BS!K42 -> -919.79094 | L11: =BS!K42-BS!L42 -> -965.78049 | M11: = Inventories year 1 - Inventories year 2 (from BS) | T11: CFF
B12: Change in trade receivables | H12: =BS!G43-BS!H43 -> -125.9 | I12: =BS!H43-BS!I43 -> -132.195 | J12: =BS!I43-BS!J43 -> -138.80475 | K12: =BS!J43-BS!K43 -> -145.74499 | L12: =BS!K43-BS!L43 -> -153.03224 | M12: = trade receivables year 1 - trade receivablesyear 2 (from BS) | T12: CFO + CFI = FCFF
B13: Change in other operating assets | H13: =BS!G44-BS!H44 -> -580.7 | I13: =BS!H44-BS!I44 -> -609.735 | J13: =BS!I44-BS!J44 -> -640.22175 | K13: =BS!J44-BS!K44 -> -672.23284 | L13: =BS!K44-BS!L44 -> -705.84448 | M13: = Other operating assets year 1 - Other operating assets year 2 (from BS)
B15: Change in trade payables | H15: =-BS!G46+BS!H46 -> 509.1 | I15: =-BS!H46+BS!I46 -> 534.555 | J15: =-BS!I46+BS!J46 -> 561.28275 | K15: =-BS!J46+BS!K46 -> 589.34689 | L15: =-BS!K46+BS!L46 -> 618.81423 | M15: = trade payables year 2 - year 1 | T15: Assets go up, cash goes down
B16: Change in other operating liabilities | H16: =-BS!G47+BS!H47 -> 898.3 | I16: =-BS!H47+BS!I47 -> 943.215 | J16: =-BS!I47+BS!J47 -> 990.37575 | K16: =-BS!J47+BS!K47 -> 1039.8945 | L16: =-BS!K47+BS!L47 -> 1091.8893 | M16: =other operating liabilities year 2 - year 1 | T16: ex) when buying PP&E, you buy in cash
B17: Cash inflow / outflow from operating activities | H17: =SUM(H5:H16) -> 14288.315 | I17: =SUM(I5:I16) -> 15035.393 | J17: =SUM(J5:J16) -> 15813.52 | K17: =SUM(K5:K16) -> 16626.659 | L17: =SUM(L5:L16) -> 17477.418
T18: Liabilities up, Cash up
B19: Investments in intangible assets | H19: =-BS!H69 -> -4725 | I19: =-BS!I69 -> -4961.25 | J19: =-BS!J69 -> -5209.3125 | K19: =-BS!K69 -> -5469.7781 | L19: =-BS!L69 -> -5743.267 | M19: = - Addition to Intangibles (from BS)
B20: Capex (PP&E Purchase) | H20: =-BS!H78 -> -8400 | I20: =-BS!I78 -> -8820 | J20: =-BS!J78 -> -9261 | K20: =-BS!K78 -> -9724.05 | L20: =-BS!L78 -> -10210.253 | M20: = -Capex (from BS)
B21: Other changes to investments
B22: Cash inflow / outflow from investing activities | H22: =SUM(H19:H21) -> -13125 | I22: =SUM(I19:I21) -> -13781.25 | J22: =SUM(J19:J21) -> -14470.313 | K22: =SUM(K19:K21) -> -15193.828 | L22: =SUM(L19:L21) -> -15953.52
B24: Payment of dividend | H24: =-IS!H23 -> -2603.2864 | I24: =-IS!I23 -> -2697.1005 | J24: =-IS!J23 -> -2802.6229 | K24: =-IS!K23 -> -2917.7545 | L24: =-IS!L23 -> -3042.0236 | M24: = - Dividends (from IS)
B25: Interest paid | H25: =-H6 -> -430.76683 | I25: =-I6 -> -492.7478 | J25: =-J6 -> -554.78799 | K25: =-K6 -> -619.108 | L25: =-L6 -> -684.89255 | M25: = - H6
B26: Proceeds from the issue of bonds | H26: =BS!H87 -> 4000 | I26: =BS!I87 -> 4000 | J26: =BS!J87 -> 4000 | K26: =BS!K87 -> 4000 | L26: =BS!L87 -> 4000 | M26: = Borrowed LT Debt (from BS)
B27: Repayment of bonds
B28: Other changes to LT liabilities
B29: Change in ST Debt | H29: =BS!H93 -> 1000 | I29: =BS!I93 -> 1000 | J29: =BS!J93 -> 1000 | K29: =BS!K93 -> 1000 | L29: =BS!L93 -> 1000 | M29: = Borrowed ST Debt (from BS)
B30: Cash inflow / outflow from financing activities | H30: =SUM(H24:H29) -> 1965.9468 | I30: =SUM(I24:I29) -> 1810.1517 | J30: =SUM(J24:J29) -> 1642.5891 | K30: =SUM(K24:K29) -> 1463.1375 | L30: =SUM(L24:L29) -> 1273.0838
B32: Change in cash and cash equivalents | H32: =H17+H22+H30 -> 3129.2619 | I32: =I17+I22+I30 -> 3064.295 | J32: =J17+J22+J30 -> 2985.7966 | K32: =K17+K22+K30 -> 2895.9687 | L32: =L17+L22+L30 -> 2796.9819 | M32: = CFO + CFI + CFF
B33: Cash and cash equivalents as at 1 January | H33: =BS!G15 -> 12036 | I33: =BS!H15 -> 15165.262 | J33: =BS!I15 -> 18229.557 | K33: =BS!J15 -> 21215.353 | L33: =BS!K15 -> 24111.322 | M33: = Cash and cash equivalents previous year
B34: Cash and cash equivalents as at 31 December | H34: =SUM(H32:H33) -> 15165.262 | I34: =SUM(I32:I33) -> 18229.557 | J34: =SUM(J32:J33) -> 21215.353 | K34: =SUM(K32:K33) -> 24111.322 | L34: =SUM(L32:L33) -> 26908.304
B36: = ending cash balance = Beginning cash balance + Change in cash (CFO + CFI + CFF)
